Workbook

Sheet Instructions

Sheet Tray Configuration
B2: Operator Name | D2: Delaney Peterson | J2: Run Start Time
B3: Sampling Loaction | D3: Konza Prairie Biological Station | J3: 44587.76
B4: Sampling Date | D4: Summer 2021
B5: Project | D5: AIMS
B6: Notes | D6: Changed vaporization module septa before run; if samples are dates 20210607, 95% of them were undated and this was drawn from the couple that were. Other samples that have different dates were pulled from dated bottles
B12: TRAY
A14: 99 | B14: WAIS_04M09_1_RAW_20210810_S | C14: WAIS_04W03_1_RAW_20210809 | D14: WAIS_04W04_1_RAW_20210809 | E14: Ouachita | F14: Sipsey | G14: Iceland | H14: Ouachita
A15: 92 | B15: WAIS_04M03_1_RAW_20210809 | C15: WAIS_04M04_1_RAW_20210809 | D15: WAIS_04M05_1_RAW_20210810_S | E15: WAIS_04M06_1_RAW_20210809 | F15: WAIS_02M07_1_RAW_20210809 | G15: WAIS_04M08_1_RAW_20210809 | H15: Ouachita | I15: 14
A16: 85 | B16: WAIS_SFT01_1_RAW_20210809 | C16: WAIS_01M01_1_RAW_20210809 | D16: WAIS_01M05_1_RAW_20210809 | E16: WAIS_02M05_1_RAW_20210809 | F16: WAIS_02M06_1_RAW_20210809 | G16: WAIS_04M01_1_RAW_20210809 | H16: Ouachita | I16: 13
A17: 78 | B17: WAIS_04M04_1_RAW_20210713 | C17: WAIS_04M06_1_RAW_20210713 | D17: WAIS_04M08_1_RAW_20210713 | E17: WAIS_04W03_1_RAW_20210713 | F17: WAIS_04W04_1_RAW_20210713 | G17: WAIS_N04D_1_RAW_20210723 | H17: Ouachita | I17: 12
A18: 71 | B18: WAIS_02M05_1_RAW_20210713 | C18: WAIS_02M07_1_RAW_20210713 | D18: WAIS_02M10_1_RAW_20210713 | E18: WAIS_02M11_1_RAW_20210713 | F18: WAIS_04M01_1_RAW_20210713 | G18: WAIS_04M03_1_RAW_20210713 | H18: Ouachita | I18: 11
A19: 64 | B19: WAIS_01M05_1_RAW_20210713 | C19: WAIS_20M05_1_RAW_20210713 | D19: WAIS_02M05_1_RAW_20210713 | E19: Ouachita | F19: Sipsey | G19: Iceland | H19: Ouachita | I19: 10
A20: 57 | B20: WAIS_04W04_1_RAW_20210607 | C20: WAIS_04T02_1_RAW_20210607 | D20: WAIS_SFM01_1_RAW_20210723 | E20: WAIS_SFM05_1_RAW_20210713 | F20: WAIS_SFT01_1_RAW_20210713 | G20: WAIS_01M02_1_RAW_20210713 | H20: Ouachita | I20: 9
A21: 50 | B21: WAIS_04M07_1_RAW_20210607 | C21: WAIS_04M08_1_RAW__20210607 | D21: WAIS_04M10_1_RAW_20210607 | E21: WAIS_04M11_1_RAW_20210607 | F21: WAIS_04W03_1_RAW_20210607 | G21: WAIS_04W02_1_RAW_20210607 | H21: Ouachita | I21: 8
A22: 43 | B22: WAIS_02M10_1_RAW_20210607 | C22: WAIS_02M11_1_RAW_20210607 | D22: WAIS_04M01_1_RAW_20210607 | E22: WAIS_04M03_1_RAW_20210607 | F22: WAIS_04M04_1_RAW_20210607 | G22: WAIS_04M06_1_RAW_20210607 | H22: Ouachita | I22: 7
A23: 36 | B23: WAIS_04M02_2_RAW_20210607 | C23: WAIS_04M05_2_RAW_20210607 | D23: WAIS_04M09_2_RAW_20210607 | E23: WAIS_02M04_1_RAW_20210607 | F23: WAIS_02M05_1_RAW_20210607 | G23: WAIS_02M08_1_RAW_20210607 | H23: Ouachita | I23: 6
A24: 29 | B24: WAIS_02M05_1_RAW_20210607_spring | C24: WAIS_02M06_1_RAW_20210607 | D24: WAIS_02M07_1_RAW_20210607 | E24: Ouachita | F24: Sipsey | G24: Iceland | H24: Ouachita | I24: 5
A25: 22 | B25: WAIS_01M06_1_RAW_20210607 | C25: WAIS_20M04_1_RAW_20210607 | D25: WAIS_20M05_1_RAW_20210607 | E25: WAIS_02M01_1_RAW_20210607 | F25: WAIS_02M02_1_RAW_20210607 | G25: WAIS_02M03_1_RAW_20210607 | H25: Ouachita | I25: 4
A26: 15 | B26: WAIS_SFT02_1_RAW_20210606 | C26: WAIS_01M01_1_RAW_20210607 | D26: WAIS_01M02_1_RAW_20210607 | E26: WAIS_01M03_1_RAW_20210607 | F26: WAIS_01M04_1_RAW_20210607 | G26: WAIS_01M05_1_RAW_20210607 | H26: Ouachita | I26: 3
A27: 8 | B27: WAIS_SFM03_1_RAW_20210607 | C27: WAIS_SFM04_1_RAW_20210607 | D27: WAIS_SFM05_1_RAW_20210607 | E27: WAIS_SFM06_1_RAW_20210607 | F27: WAIS_SFM07_1_RAW_20210607 | G27: WAIS_SFT01_1_RAW_20210606 | H27: Ouachita | I27: 2
A28: 1 | B28: Ouachita | C28: Sipsey | D28: Iceland | E28: Ouachita | F28: Ouachita | G28: WAIS_SFM01_2_RAW_20210607 | H28: WAIS_SFM02_1_RAW_20210607
B29: 1 | C29: 2 | D29: 3 | E29: 4 | F29: 5 | G29: 6 | H29: 7
B32: Standards
C33: Standard ID | D33: Actual d(18_16) | E33: Actual d(D_H)
B34: #1 | C34: Iceland | D34: -8 | E34: -52.8
B35: #2 | C35: Ouachita | D35: -5.5 | E35: -29.6
B36: #3 | C36: Sipsey | D36: -4.5 | E36: -22.4
B37: #4
B38: #5
B39: #6
B40: #7
B41: #8
B42: #9
B43: #10
B44: #11
B45: #12

Sheet Timing
A1: Enter start time and date --> | C1: 44587.76
A2: Tray Position | B2: Sample ID | C2: Start Time | D2: # Injections
A3: 1 | B3: ='Tray Configuration'!B28 -> Ouachita | C3: =C1 -> 44587.76 | D3: 15
A4: 2 | B4: ='Tray Configuration'!C28 -> Sipsey | C4: =C3+"0:08:57"*D3 -> 44587.854 | D4: 15
A5: 3 | B5: ='Tray Configuration'!D28 -> Iceland | C5: =C4+"0:08:57"*D4 -> 44587.947 | D5: 15
A6: 4 | B6: ='Tray Configuration'!E28 -> Ouachita | C6: =C5+"0:08:57"*D5 -> 44588.04 | D6: 15
A7: 5 | B7: ='Tray Configuration'!F28 -> Ouachita | C7: =C6+"0:08:57"*D6 -> 44588.133 | D7: 15
A8: 6 | B8: ='Tray Configuration'!G28 -> WAIS_SFM01_2_RAW_20210607 | C8: =C7+"0:08:57"*D7 -> 44588.227 | D8: 6
A9: 7 | B9: ='Tray Configuration'!H28 -> WAIS_SFM02_1_RAW_20210607 | C9: =C8+"0:08:57"*D8 -> 44588.264 | D9: 6
A10: 8 | B10: ='Tray Configuration'!B27 -> WAIS_SFM03_1_RAW_20210607 | C10: =C9+"0:08:57"*D9 -> 44588.301 | D10: 6
A11: 9 | B11: ='Tray Configuration'!C27 -> WAIS_SFM04_1_RAW_20210607 | C11: =C10+"0:08:57"*D10 -> 44588.338 | D11: 6
A12: 10 | B12: ='Tray Configuration'!D27 -> WAIS_SFM05_1_RAW_20210607 | C12: =C11+"0:08:57"*D11 -> 44588.376 | D12: 6
A13: 11 | B13: ='Tray Configuration'!E27 -> WAIS_SFM06_1_RAW_20210607 | C13: =C12+"0:08:57"*D12 -> 44588.413 | D13: 6
A14: 12 | B14: ='Tray Configuration'!F27 -> WAIS_SFM07_1_RAW_20210607 | C14: =C13+"0:08:57"*D13 -> 44588.45 | D14: 6
A15: 13 | B15: ='Tray Configuration'!G27 -> WAIS_SFT01_1_RAW_20210606 | C15: =C14+"0:08:57"*D14 -> 44588.488 | D15: 6
A16: 14 | B16: ='Tray Configuration'!H27 -> Ouachita | C16: =C15+"0:08:57"*D15 -> 44588.525 | D16: 6
A17: 15 | B17: ='Tray Configuration'!B26 -> WAIS_SFT02_1_RAW_20210606 | C17: =C16+"0:08:57"*D16 -> 44588.562 | D17: 6
A18: 16 | B18: ='Tray Configuration'!C26 -> WAIS_01M01_1_RAW_20210607 | C18: =C17+"0:08:57"*D17 -> 44588.599 | D18: 6
A19: 17 | B19: ='Tray Configuration'!D26 -> WAIS_01M02_1_RAW_20210607 | C19: =C18+"0:08:57"*D18 -> 44588.637 | D19: 6
A20: 18 | B20: ='Tray Configuration'!E26 -> WAIS_01M03_1_RAW_20210607 | C20: =C19+"0:08:57"*D19 -> 44588.674 | D20: 6
A21: 19 | B21: ='Tray Configuration'!F26 -> WAIS_01M04_1_RAW_20210607 | C21: =C20+"0:08:57"*D20 -> 44588.711 | D21: 6
A22: 20 | B22: ='Tray Configuration'!G26 -> WAIS_01M05_1_RAW_20210607 | C22: =C21+"0:08:57"*D21 -> 44588.749 | D22: 6
A23: 21 | B23: ='Tray Configuration'!H26 -> Ouachita | C23: =C22+"0:08:57"*D22 -> 44588.786 | D23: 6
A24: 22 | B24: ='Tray Configuration'!B25 -> WAIS_01M06_1_RAW_20210607 | C24: =C23+"0:08:57"*D23 -> 44588.823 | D24: 6
A25: 23 | B25: ='Tray Configuration'!C25 -> WAIS_20M04_1_RAW_20210607 | C25: =C24+"0:08:57"*D24 -> 44588.861 | D25: 6
A26: 24 | B26: ='Tray Configuration'!D25 -> WAIS_20M05_1_RAW_20210607 | C26: =C25+"0:08:57"*D25 -> 44588.898 | D26: 6
A27: 25 | B27: ='Tray Configuration'!E25 -> WAIS_02M01_1_RAW_20210607 | C27: =C26+"0:08:57"*D26 -> 44588.935 | D27: 6
A28: 26 | B28: ='Tray Configuration'!F25 -> WAIS_02M02_1_RAW_20210607 | C28: =C27+"0:08:57"*D27 -> 44588.972 | D28: 6
A29: 27 | B29: ='Tray Configuration'!G25 -> WAIS_02M03_1_RAW_20210607 | C29: =C28+"0:08:57"*D28 -> 44589.01 | D29: 6
A30: 28 | B30: ='Tray Configuration'!H25 -> Ouachita | C30: =C29+"0:08:57"*D29 -> 44589.047 | D30: 6
A31: 29 | B31: ='Tray Configuration'!B24 -> WAIS_02M05_1_RAW_20210607_spring | C31: =C30+"0:08:57"*D30 -> 44589.084 | D31: 6
A32: 30 | B32: ='Tray Configuration'!C24 -> WAIS_02M06_1_RAW_20210607 | C32: =C31+"0:08:57"*D31 -> 44589.122 | D32: 6
A33: 31 | B33: ='Tray Configuration'!D24 -> WAIS_02M07_1_RAW_20210607 | C33: =C32+"0:08:57"*D32 -> 44589.159 | D33: 6
A34: 32 | B34: ='Tray Configuration'!E24 -> Ouachita | C34: =C33+"0:08:57"*D33 -> 44589.196 | D34: 15
A35: 33 | B35: ='Tray Configuration'!F24 -> Sipsey | C35: =C34+"0:08:57"*D34 -> 44589.289 | D35: 15
A36: 34 | B36: ='Tray Configuration'!G24 -> Iceland | C36: =C35+"0:08:57"*D35 -> 44589.383 | D36: 15
A37: 35 | B37: ='Tray Configuration'!H24 -> Ouachita | C37: =C36+"0:08:57"*D36 -> 44589.476 | D37: 15
A38: 36 | B38: ='Tray Configuration'!B23 -> WAIS_04M02_2_RAW_20210607 | C38: =C37+"0:08:57"*D37 -> 44589.569 | D38: 6
A39: 37 | B39: ='Tray Configuration'!C23 -> WAIS_04M05_2_RAW_20210607 | C39: =C38+"0:08:57"*D38 -> 44589.606 | D39: 6
A40: 38 | B40: ='Tray Configuration'!D23 -> WAIS_04M09_2_RAW_20210607 | C40: =C39+"0:08:57"*D39 -> 44589.644 | D40: 6
...

Sheet Picarro Output
A1: Line | B1: Analysis | C1: Time Code | D1: Port | E1: Inj Nr | F1: d(18_16)Mean | G1: d(D_H)Mean | H1: H2O_Mean | I1: Ignore | J1: Good | K1: Identifier 1 | L1: Identifier 2 | M1: Gas Configuration | N1: Timestamp Mean | O1: d(18_16)_SD | P1: d(D_H)_SD | Q1: H2O_SD | R1: d(18_16)_Sl | S1: d(D_H)_Sl | T1: H2O_Sl | U1: baseline_shift | V1: slope_shift | W1: residuals | X1: baseline_curvature | Y1: interval | Z1: ch4_ppm | AA1: h16od_adjust | AB1: h16od_shift | AC1: n2_flag | AD1: DAS Temp | AE1: Tray | AF1: Sample | AG1: Job | AH1: Method | AI1: Error Code
A2: 1 | B2: P-238 | C2: 2022/01/26 18:16:52 | D2: 1-01 | E2: 1 | F2: -6.157 | G2: -35.965 | H2: 15927 | I2: -1 | J2: 1 | M2: H2O | N2: 1.6432429e+09 | O2: 0.436 | P2: 0.71 | Q2: 63.462 | R2: -0.006 | S2: -0.008 | T2: 1.528 | U2: 90.904 | V2: 16.731 | W2: 2.373 | X2: 93.124 | Y2: 0.9 | Z2: 0.19 | AA2: 0.0012 | AB2: 0.0012 | AC2: 1 | AD2: 39.562 | AE2: 1 | AF2: 1 | AG2: 1 | AH2: Picarro | AI2: 0
A3: 2 | B3: P-238 | C3: 2022/01/26 18:25:50 | D3: 1-01 | E3: 2 | F3: -5.803 | G3: -32.537 | H3: 16178 | I3: -1 | J3: 1 | M3: H2O | N3: 1.6432435e+09 | O3: 0.203 | P3: 0.438 | Q3: 56.777 | R3: 0 | S3: -0.004 | T3: 1.36 | U3: 91.161 | V3: 23.036 | W3: 2.174 | X3: 85.009 | Y3: 0.901 | Z3: 0.369 | AA3: 0 | AB3: 0 | AC3: 1 | AD3: 39.5 | AE3: 1 | AF3: 1 | AG3: 1 | AH3: Picarro | AI3: 0
A4: 3 | B4: P-238 | C4: 2022/01/26 18:34:47 | D4: 1-01 | E4: 3 | F4: -5.731 | G4: -31.58 | H4: 16185 | I4: -1 | J4: 1 | M4: H2O | N4: 1643243993 | O4: 0.197 | P4: 0.435 | Q4: 55.37 | R4: 0 | S4: -0.004 | T4: 1.33 | U4: 90.341 | V4: 24.695 | W4: 2.189 | X4: 84.618 | Y4: 0.899 | Z4: 0.676 | AA4: 0 | AB4: 0 | AC4: 1 | AD4: 39.5 | AE4: 1 | AF4: 1 | AG4: 1 | AH4: Picarro | AI4: 0
A5: 4 | B5: P-238 | C5: 2022/01/26 18:43:45 | D5: 1-01 | E5: 4 | F5: -5.645 | G5: -31.138 | H5: 16175 | I5: 0 | J5: 1 | M5: H2O | N5: 1.6432445e+09 | O5: 0.208 | P5: 0.437 | Q5: 56.118 | R5: 0 | S5: -0.002 | T5: 1.359 | U5: 90.167 | V5: 25.021 | W5: 2.225 | X5: 83.913 | Y5: 0.905 | Z5: 0.715 | AA5: 0 | AB5: 0 | AC5: 1 | AD5: 39.5 | AE5: 1 | AF5: 1 | AG5: 1 | AH5: Picarro | AI5: 0
A6: 5 | B6: P-238 | C6: 2022/01/26 18:52:42 | D6: 1-01 | E6: 5 | F6: -5.657 | G6: -30.907 | H6: 16300 | I6: 0 | J6: 1 | M6: H2O | N6: 1.6432451e+09 | O6: 0.208 | P6: 0.401 | Q6: 55.642 | R6: 0.001 | S6: -0.003 | T6: 1.332 | U6: 90.885 | V6: 24.356 | W6: 2.357 | X6: 87.427 | Y6: 0.907 | Z6: 1.038 | AA6: 0 | AB6: 0 | AC6: 1 | AD6: 39.5 | AE6: 1 | AF6: 1 | AG6: 1 | AH6: Picarro | AI6: 0
A7: 6 | B7: P-238 | C7: 2022/01/26 19:01:39 | D7: 1-01 | E7: 6 | F7: -5.666 | G7: -30.648 | H7: 16353 | I7: 0 | J7: 1 | M7: H2O | N7: 1.6432456e+09 | O7: 0.207 | P7: 0.436 | Q7: 55.548 | R7: 0 | S7: -0.001 | T7: 1.337 | U7: 91.151 | V7: 24.013 | W7: 2.427 | X7: 88.913 | Y7: 0.898 | Z7: 1.211 | AA7: 0 | AB7: 0 | AC7: 1 | AD7: 39.438 | AE7: 1 | AF7: 1 | AG7: 1 | AH7: Picarro | AI7: 0
A8: 7 | B8: P-238 | C8: 2022/01/26 19:10:37 | D8: 1-01 | E8: 7 | F8: -5.609 | G8: -30.593 | H8: 16278 | I8: 0 | J8: 1 | M8: H2O | N8: 1.6432461e+09 | O8: 0.212 | P8: 0.375 | Q8: 55.511 | R8: 0.001 | S8: -0.001 | T8: 1.336 | U8: 90.466 | V8: 24.631 | W8: 2.359 | X8: 87.803 | Y8: 0.9 | Z8: 1.221 | AA8: 0 | AB8: 0 | AC8: 1 | AD8: 39.5 | AE8: 1 | AF8: 1 | AG8: 1 | AH8: Picarro | AI8: 0
A9: 8 | B9: P-238 | C9: 2022/01/26 19:19:35 | D9: 1-01 | E9: 8 | F9: -5.621 | G9: -30.379 | H9: 16283 | I9: 0 | J9: 1 | M9: H2O | N9: 1.6432467e+09 | O9: 0.189 | P9: 0.436 | Q9: 55.472 | R9: 0 | S9: -0.003 | T9: 1.33 | U9: 90.246 | V9: 25.88 | W9: 2.259 | X9: 85.148 | Y9: 0.914 | Z9: 1.022 | AA9: 0 | AB9: 0 | AC9: 1 | AD9: 39.5 | AE9: 1 | AF9: 1 | AG9: 1 | AH9: Picarro | AI9: 0
A10: 9 | B10: P-238 | C10: 2022/01/26 19:28:32 | D10: 1-01 | E10: 9 | F10: -5.652 | G10: -30.399 | H10: 16276 | I10: 0 | J10: 1 | M10: H2O | N10: 1643247218 | O10: 0.189 | P10: 0.419 | Q10: 56.209 | R10: 0.001 | S10: -0.002 | T10: 1.349 | U10: 90.19 | V10: 26.11 | W10: 2.235 | X10: 84.381 | Y10: 0.909 | Z10: 0.904 | AA10: 0 | AB10: 0 | AC10: 1 | AD10: 39.5 | AE10: 1 | AF10: 1 | AG10: 1 | AH10: Picarro | AI10: 0
A11: 10 | B11: P-238 | C11: 2022/01/26 19:37:30 | D11: 1-01 | E11: 10 | F11: -5.631 | G11: -30.408 | H11: 16311 | I11: 0 | J11: 1 | M11: H2O | N11: 1.6432478e+09 | O11: 0.185 | P11: 0.397 | Q11: 55.61 | R11: 0 | S11: -0.002 | T11: 1.335 | U11: 90.557 | V11: 25.904 | W11: 2.221 | X11: 84.609 | Y11: 0.905 | Z11: 0.807 | AA11: 0 | AB11: 0 | AC11: 1 | AD11: 39.5 | AE11: 1 | AF11: 1 | AG11: 1 | AH11: Picarro | AI11: 0
A12: 11 | B12: P-238 | C12: 2022/01/26 19:46:27 | D12: 1-01 | E12: 11 | F12: -5.646 | G12: -30.394 | H12: 16297 | I12: 0 | J12: 1 | M12: H2O | N12: 1.6432483e+09 | O12: 0.183 | P12: 0.447 | Q12: 56.484 | R12: 0 | S12: 0 | T12: 1.356 | U12: 90.584 | V12: 25.667 | W12: 2.237 | X12: 84.341 | Y12: 0.908 | Z12: 0.875 | AA12: 0 | AB12: 0 | AC12: 1 | AD12: 39.5 | AE12: 1 | AF12: 1 | AG12: 1 | AH12: Picarro | AI12: 0
A13: 12 | B13: P-238 | C13: 2022/01/26 19:55:24 | D13: 1-01 | E13: 12 | F13: -5.579 | G13: -30.264 | H13: 16257 | I13: 0 | J13: 1 | M13: H2O | N13: 1.6432488e+09 | O13: 0.201 | P13: 0.426 | Q13: 56.456 | R13: 0.001 | S13: 0 | T13: 1.354 | U13: 90.634 | V13: 25.202 | W13: 2.163 | X13: 83.927 | Y13: 0.926 | Z13: 0.594 | AA13: 0 | AB13: 0 | AC13: 1 | AD13: 39.5 | AE13: 1 | AF13: 1 | AG13: 1 | AH13: Picarro | AI13: 0
... A400: 399 | B400: P-290 | C400: 2022/01/29 05:38:55 | D400: 1-53 | E400: 6 | F400: -5.988 | G400: -37.067 | H400: 16123 | I400: 0 | J400: 1 | M400: H2O | N400: 1.6434566e+09 | O400: 0.206 | P400: 0.437 | Q400: 53.997 | R400: 0.001 | S400: 0.002 | T400: 1.302 | U400: 89.756 | V400: 24.54 | W400: 2.256 | X400: 85.048 | Y400: 0.905 | Z400: 0.947 | AA400: 0 | AB400: 0 | AC400: 1 | AD400: 39.438 | AE400: 1 | AF400: 53 | AG400: 4 | AH400: Picarro | AI400: 0
A401: 400 | B401: P-291 | C401: 2022/01/29 05:47:52 | D401: 1-54 | E401: 1 | M401: H2O | AE401: 1 | AF401: 54 | AG401: 4 | AH401: Picarro | AI401: 0
A402: 401 | B402: P-291 | C402: 2022/01/29 05:57:52 | D402: 1-54 | E402: 2 | F402: -5.929 | G402: -36.757 | H402: 16069 | I402: -1 | J402: 1 | M402: H2O | N402: 1.6434578e+09 | O402: 0.215 | P402: 0.469 | Q402: 46.53 | R402: 0.001 | S402: 0.002 | T402: 1.12 | U402: 89.295 | V402: 24.504 | W402: 2.315 | X402: 85.63 | Y402: 0.903 | Z402: 1.121 | AA402: 0 | AB402: 0 | AC402: 1 | AD402: 39.5 | AE402: 1 | AF402: 54 | AG402: 4 | AH402: Picarro | AI402: 0
A403: 402 | B403: P-291 | C403: 2022/01/29 06:06:50 | D403: 1-54 | E403: 3 | F403: -5.896 | G403: -36.716 | H403: 16137 | I403: -1 | J403: 1 | M403: H2O | N403: 1.6434583e+09 | O403: 0.215 | P403: 0.375 | Q403: 51.179 | R403: 0.001 | S403: 0.002 | T403: 1.225 | U403: 89.73 | V403: 24.797 | W403: 2.257 | X403: 85.106 | Y403: 0.897 | Z403: 0.951 | AA403: 0 | AB403: 0 | AC403: 1 | AD403: 39.438 | AE403: 1 | AF403: 54 | AG403: 4 | AH403: Picarro | AI403: 0
A404: 403 | B404: P-291 | C404: 2022/01/29 06:15:46 | D404: 1-54 | E404: 4 | F404: -5.912 | G404: -36.751 | H404: 16178 | I404: 0 | J404: 1 | M404: H2O | N404: 1.6434589e+09 | O404: 0.234 | P404: 0.399 | Q404: 52.308 | R404: 0.002 | S404: 0.002 | T404: 1.255 | U404: 90.155 | V404: 24.505 | W404: 2.283 | X404: 85.366 | Y404: 0.895 | Z404: 0.965 | AA404: 0 | AB404: 0 | AC404: 1 | AD404: 39.5 | AE404: 1 | AF404: 54 | AG404: 4 | AH404: Picarro | AI404: 0
A405: 404 | B405: P-291 | C405: 2022/01/29 06:24:43 | D405: 1-54 | E405: 5 | F405: -5.924 | G405: -36.737 | H405: 16192 | I405: 0 | J405: 1 | M405: H2O | N405: 1.6434594e+09 | O405: 0.193 | P405: 0.448 | Q405: 51.961 | R405: 0.001 | S405: 0.001 | T405: 1.253 | U405: 90.43 | V405: 24.287 | W405: 2.24 | X405: 85.225 | Y405: 0.897 | Z405: 0.828 | AA405: 0 | AB405: 0 | AC405: 1 | AD405: 39.438 | AE405: 1 | AF405: 54 | AG405: 4 | AH405: Picarro | AI405: 0
A406: 405 | B406: P-291 | C406: 2022/01/29 06:33:40 | D406: 1-54 | E406: 6 | F406: -5.902 | G406: -36.637 | H406: 16205 | I406: 0 | J406: 1 | M406: H2O | N406: 1.6434599e+09 | O406: 0.221 | P406: 0.433 | Q406: 52.435 | R406: 0.001 | S406: 0 | T406: 1.265 | U406: 90.233 | V406: 24.721 | W406: 2.317 | X406: 85.186 | Y406: 0.908 | Z406: 0.973 | AA406: 0 | AB406: 0 | AC406: 1 | AD406: 39.438 | AE406: 1 | AF406: 54 | AG406: 4 | AH406: Picarro | AI406: 0
A407: 406 | B407: P-292 | C407: 2022/01/29 06:42:37 | D407: 1-55 | E407: 1 | F407: -5.864 | G407: -36.377 | H407: 16223 | I407: -1 | J407: 1 | M407: H2O | N407: 1.6434605e+09 | O407: 0.209 | P407: 0.478 | Q407: 53.381 | R407: 0.001 | S407: 0 | T407: 1.279 | U407: 90.248 | V407: 24.504 | W407: 2.317 | X407: 86.776 | Y407: 0.9 | Z407: 1.179 | AA407: 0 | AB407: 0 | AC407: 1 | AD407: 39.375 | AE407: 1 | AF407: 55 | AG407: 4 | AH407: Picarro | AI407: 0
A408: 407 | B408: P-292 | C408: 2022/01/29 06:51:34 | D408: 1-55 | E408: 2 | F408: -5.879 | G408: -36.351 | H408: 16214 | I408: -1 | J408: 1 | M408: H2O | N408: 1.643461e+09 | O408: 0.21 | P408: 0.412 | Q408: 53.126 | R408: 0.001 | S408: 0 | T408: 1.277 | U408: 90.135 | V408: 24.575 | W408: 2.333 | X408: 86.778 | Y408: 0.889 | Z408: 1.291 | AA408: 0 | AB408: 0 | AC408: 1 | AD408: 39.438 | AE408: 1 | AF408: 55 | AG408: 4 | AH408: Picarro | AI408: 0
A409: 408 | B409: P-292 | C409: 2022/01/29 07:00:31 | D409: 1-55 | E409: 3 | F409: -5.834 | G409: -36.342 | H409: 16211 | I409: -1 | J409: 1 | M409: H2O | N409: 1.6434615e+09 | O409: 0.209 | P409: 0.431 | Q409: 53.801 | R409: 0.001 | S409: 0 | T409: 1.291 | U409: 90.121 | V409: 24.776 | W409: 2.322 | X409: 86.151 | Y409: 0.902 | Z409: 0.97 | AA409: 0 | AB409: 0 | AC409: 1 | AD409: 39.438 | AE409: 1 | AF409: 55 | AG409: 4 | AH409: Picarro | AI409: 0
A410: 409 | B410: P-292 | C410: 2022/01/29 07:09:28 | D410: 1-55 | E410: 4 | F410: -5.828 | G410: -36.306 | H410: 16142 | I410: 0 | J410: 1 | M410: H2O | N410: 1.6434621e+09 | O410: 0.19 | P410: 0.408 | Q410: 53.52 | R410: 0 | S410: 0 | T410: 1.289 | U410: 89.85 | V410: 24.565 | W410: 2.291 | X410: 85.248 | Y410: 0.907 | Z410: 1.057 | AA410: 0 | AB410: 0 | AC410: 1 | AD410: 39.375 | AE410: 1 | AF410: 55 | AG410: 4 | AH410: Picarro | AI410: 0
A411: 410 | B411: P-292 | C411: 2022/01/29 07:18:25 | D411: 1-55 | E411: 5 | F411: -5.828 | G411: -36.339 | H411: 16250 | I411: 0 | J411: 1 | M411: H2O | N411: 1.6434626e+09 | O411: 0.218 | P411: 0.422 | Q411: 53.56 | R411: 0.001 | S411: 0.001 | T411: 1.286 | U411: 90.471 | V411: 24.599 | W411: 2.33 | X411: 86.586 | Y411: 0.9 | Z411: 1.069 | AA411: 0 | AB411: 0 | AC411: 1 | AD411: 39.438 | AE411: 1 | AF411: 55 | AG411: 4 | AH411: Picarro | AI411: 0
A412: 411 | B412: P-292 | C412: 2022/01/29 07:27:21 | D412: 1-55 | E412: 6 | F412: -5.824 | G412: -36.296 | H412: 16170 | I412: 0 | J412: 1 | M412: H2O | N412: 1.6434631e+09 | O412: 0.214 | P412: 0.414 | Q412: 53.044 | R412: 0.002 | S412: 0.002 | T412: 1.284 | U412: 90.019 | V412: 24.862 | W412: 2.256 | X412: 84.718 | Y412: 0.906 | Z412: 0.889 | AA412: 0 | AB412: 0 | AC412: 1 | AD412: 39.312 | AE412: 1 | AF412: 55 | AG412: 4 | AH412: Picarro | AI412: 0
A413: 412 | B413: P-293 | C413: 2022/01/29 07:36:17 | D413: 1-56 | E413: 1 | F413: -5.508 | G413: -30.16 | H413: 16224 | I413: -1 | J413: 1 | M413: H2O | N413: 1.6434637e+09 | O413: 0.203 | P413: 0.379 | Q413: 52.546 | R413: 0.001 | S413: 0.001 | T413: 1.263 | U413: 90.366 | V413: 24.117 | W413: 2.331 | X413: 87.706 | Y413: 0.9 | Z413: 1.213 | AA413: 0 | AB413: 0 | AC413: 1 | AD413: 39.438 | AE413: 1 | AF413: 56 | AG413: 4 | AH413: Picarro | AI413: 0
... A784: 783 | B784: P-342 | C784: 2022/01/31 14:53:12 | D784: 1-105 | E784: 15 | F784: -5.523 | G784: -29.381 | H784: 16279 | I784: 0 | J784: 1 | M784: H2O | N784: 1.6436627e+09 | O784: 0.194 | P784: 0.419 | Q784: 54.391 | R784: 0.001 | S784: 0.001 | T784: 1.307 | U784: 91.906 | V784: 22.278 | W784: 2.299 | X784: 88.275 | Y784: 0.969 | Z784: 0.68 | AA784: 0 | AB784: 0 | AC784: 1 | AD784: 39.688 | AE784: 1 | AF784: 105 | AG784: 7 | AH784: Picarro | AI784: 0

Sheet Uncalibrated Data
A1: Tray Position | B1: Sample ID | C1: Picarro ID | D1: d(18_16) | E1: d(D_H) | F1: Count
A2: 1 | B2: ='Tray Configuration'!B28 -> Ouachita | C2: ='Picarro Output'!B16 -> P-238 | D2: =AVERAGE('Picarro Output'!F12:F16) -> -5.6062 | E2: =AVERAGE('Picarro Output'!G12:G16) -> -30.2202 | F2: 15
A3: 2 | B3: ='Tray Configuration'!C28 -> Sipsey | C3: ='Picarro Output'!B31 -> P-239 | D3: =AVERAGE('Picarro Output'!F27:F31) -> -4.5428 | E3: =AVERAGE('Picarro Output'!G27:G31) -> -22.9288 | F3: 15
A4: 3 | B4: ='Tray Configuration'!D28 -> Iceland | C4: ='Picarro Output'!B46 -> P-240 | D4: =AVERAGE('Picarro Output'!F42:F46) -> -8.0142 | E4: =AVERAGE('Picarro Output'!G42:G46) -> -52.9894 | F4: 15
A5: 4 | B5: ='Tray Configuration'!E28 -> Ouachita | C5: ='Picarro Output'!B61 -> P-241 | D5: =AVERAGE('Picarro Output'!F57:F61) -> -5.576 | E5: =AVERAGE('Picarro Output'!G57:G61) -> -29.89 | F5: 15
A6: 5 | B6: ='Tray Configuration'!F28 -> Ouachita | C6: ='Picarro Output'!B76 -> P-242 | D6: =AVERAGE('Picarro Output'!F72:F76) -> -5.5494 | E6: =AVERAGE('Picarro Output'!G72:G76) -> -29.7474 | F6: 15
A7: 6 | B7: ='Tray Configuration'!G28 -> WAIS_SFM01_2_RAW_20210607 | C7: ='Picarro Output'!B82 -> P-243 | D7: =AVERAGE('Picarro Output'!F80:F82) -> -5.938 | E7: =AVERAGE('Picarro Output'!G80:G82) -> -36.928667 | F7: 6
A8: 7 | B8: ='Tray Configuration'!H28 -> WAIS_SFM02_1_RAW_20210607 | C8: ='Picarro Output'!B88 -> P-244 | D8: =AVERAGE('Picarro Output'!F86:F88) -> -5.959 | E8: =AVERAGE('Picarro Output'!G86:G88) -> -37.079 | F8: 6
A9: 8 | B9: ='Tray Configuration'!B27 -> WAIS_SFM03_1_RAW_20210607 | C9: ='Picarro Output'!B94 -> P-245 | D9: =AVERAGE('Picarro Output'!F84:F92) -> -5.9372222 | E9: =AVERAGE('Picarro Output'!G92:G94) -> -36.989 | F9: 6
A10: 9 | B10: ='Tray Configuration'!C27 -> WAIS_SFM04_1_RAW_20210607 | C10: ='Picarro Output'!B100 -> P-246 | D10: =AVERAGE('Picarro Output'!F98:F100) -> -5.9323333 | E10: =AVERAGE('Picarro Output'!G98:G100) -> -37.066 | F10: 6
A11: 10 | B11: ='Tray Configuration'!D27 -> WAIS_SFM05_1_RAW_20210607 | C11: ='Picarro Output'!B106 -> P-247 | D11: =AVERAGE('Picarro Output'!F104:F106) -> -5.916 | E11: =AVERAGE('Picarro Output'!G104:G106) -> -36.934667 | F11: 6
A12: 11 | B12: ='Tray Configuration'!E27 -> WAIS_SFM06_1_RAW_20210607 | C12: ='Picarro Output'!B112 -> P-248 | D12: =AVERAGE('Picarro Output'!F110:F112) -> -5.9326667 | E12: =AVERAGE('Picarro Output'!G110:G112) -> -36.963667 | F12: 6
A13: 12 | B13: ='Tray Configuration'!F27 -> WAIS_SFM07_1_RAW_20210607 | C13: ='Picarro Output'!B118 -> P-249 | D13: =AVERAGE('Picarro Output'!F116:F118) -> -5.9793333 | E13: =AVERAGE('Picarro Output'!G116:G118) -> -37.169 | F13: 6
A14: 13 | B14: ='Tray Configuration'!G27 -> WAIS_SFT01_1_RAW_20210606 | C14: ='Picarro Output'!B124 -> P-250 | D14: =AVERAGE('Picarro Output'!F122:F124) -> -5.8146667 | E14: =AVERAGE('Picarro Output'!G122:G124) -> -36.726333 | F14: 6
A15: 14 | B15: ='Tray Configuration'!H27 -> Ouachita | C15: ='Picarro Output'!B130 -> P-251 | D15: =AVERAGE('Picarro Output'!F128:F130) -> -5.5366667 | E15: =AVERAGE('Picarro Output'!G128:G130) -> -29.735333 | F15: 6
A16: 15 | B16: ='Tray Configuration'!B26 -> WAIS_SFT02_1_RAW_20210606 | C16: ='Picarro Output'!B136 -> P-252 | D16: =AVERAGE('Picarro Output'!F134:F136) -> -5.8973333 | E16: =AVERAGE('Picarro Output'!G134:G136) -> -37.146667 | F16: 6
A17: 16 | B17: ='Tray Configuration'!C26 -> WAIS_01M01_1_RAW_20210607 | C17: ='Picarro Output'!B142 -> P-253 | D17: =AVERAGE('Picarro Output'!F140:F142) -> -5.9736667 | E17: =AVERAGE('Picarro Output'!G140:G142) -> -37.333 | F17: 6
A18: 17 | B18: ='Tray Configuration'!D26 -> WAIS_01M02_1_RAW_20210607 | C18: ='Picarro Output'!B148 -> P-254 | D18: =AVERAGE('Picarro Output'!F146:F148) -> -5.9896667 | E18: =AVERAGE('Picarro Output'!G146:G148) -> -37.376 | F18: 6
A19: 18 | B19: ='Tray Configuration'!E26 -> WAIS_01M03_1_RAW_20210607 | C19: ='Picarro Output'!B154 -> P-255 | D19: =AVERAGE('Picarro Output'!F152:F154) -> -5.801 | E19: =AVERAGE('Picarro Output'!G152:G154) -> -36.581667 | F19: 6
A20: 19 | B20: ='Tray Configuration'!F26 -> WAIS_01M04_1_RAW_20210607 | C20: ='Picarro Output'!B160 -> P-256 | D20: =AVERAGE('Picarro Output'!F158:F160) -> -5.8353333 | E20: =AVERAGE('Picarro Output'!G158:G160) -> -36.758 | F20: 6
A21: 20 | B21: ='Tray Configuration'!G26 -> WAIS_01M05_1_RAW_20210607 | C21: ='Picarro Output'!B166 -> P-257 | D21: =AVERAGE('Picarro Output'!F164:F166) -> -5.8633333 | E21: =AVERAGE('Picarro Output'!G164:G166) -> -36.963333 | F21: 6
A22: 21 | B22: ='Tray Configuration'!H26 -> Ouachita | C22: ='Picarro Output'!B172 -> P-258 | D22: =AVERAGE('Picarro Output'!F170:F172) -> -5.5336667 | E22: =AVERAGE('Picarro Output'!G170:G172) -> -29.668 | F22: 6
A23: 22 | B23: ='Tray Configuration'!B25 -> WAIS_01M06_1_RAW_20210607 | C23: ='Picarro Output'!B178 -> P-259 | D23: =AVERAGE('Picarro Output'!F176:F178) -> -5.8156667 | E23: =AVERAGE('Picarro Output'!G176:G178) -> -36.568333 | F23: 6
A24: 23 | B24: ='Tray Configuration'!C25 -> WAIS_20M04_1_RAW_20210607 | C24: ='Picarro Output'!B184 -> P-260 | D24: =AVERAGE('Picarro Output'!F182:F184) -> -6.0276667 | E24: =AVERAGE('Picarro Output'!G182:G184) -> -37.152667 | F24: 6
A25: 24 | B25: ='Tray Configuration'!D25 -> WAIS_20M05_1_RAW_20210607 | C25: ='Picarro Output'!B190 -> P-261 | D25: =AVERAGE('Picarro Output'!F188:F190) -> -6.058 | E25: =AVERAGE('Picarro Output'!G188:G190) -> -37.477667 | F25: 6
A26: 25 | B26: ='Tray Configuration'!E25 -> WAIS_02M01_1_RAW_20210607 | C26: ='Picarro Output'!B196 -> P-262 | D26: =AVERAGE('Picarro Output'!F194:F196) -> -5.8323333 | E26: =AVERAGE('Picarro Output'!G194:G196) -> -36.592 | F26: 6
A27: 26 | B27: ='Tray Configuration'!F25 -> WAIS_02M02_1_RAW_20210607 | C27: ='Picarro Output'!B202 -> P-263 | D27: =AVERAGE('Picarro Output'!F200:F202) -> -5.8536667 | E27: =AVERAGE('Picarro Output'!G200:G202) -> -36.722333 | F27: 6
A28: 27 | B28: ='Tray Configuration'!G25 -> WAIS_02M03_1_RAW_20210607 | C28: ='Picarro Output'!B208 -> P-264 | D28: =AVERAGE('Picarro Output'!F206:F208) -> -5.882 | E28: =AVERAGE('Picarro Output'!G206:G208) -> -36.751667 | F28: 6
A29: 28 | B29: ='Tray Configuration'!H25 -> Ouachita | C29: ='Picarro Output'!B214 -> P-265 | D29: =AVERAGE('Picarro Output'!F212:F214) -> -5.527 | E29: =AVERAGE('Picarro Output'!G212:G214) -> -29.720333 | F29: 6
A30: 29 | B30: ='Tray Configuration'!B24 -> WAIS_02M05_1_RAW_20210607_spring | C30: ='Picarro Output'!B220 -> P-266 | D30: =AVERAGE('Picarro Output'!F218:F220) -> -5.8636667 | E30: =AVERAGE('Picarro Output'!G218:G220) -> -36.98 | F30: 6
A31: 30 | B31: ='Tray Configuration'!C24 -> WAIS_02M06_1_RAW_20210607 | C31: ='Picarro Output'!B226 -> P-267 | D31: =AVERAGE('Picarro Output'!F224:F226) -> -5.9463333 | E31: =AVERAGE('Picarro Output'!G224:G226) -> -37.042667 | F31: 6
A32: 31 | B32: ='Tray Configuration'!D24 -> WAIS_02M07_1_RAW_20210607 | C32: ='Picarro Output'!B232 -> P-268 | D32: =AVERAGE('Picarro Output'!F230:F232) -> -5.9503333 | E32: =AVERAGE('Picarro Output'!G230:G232) -> -37.159333 | F32: 6
A33: 32 | B33: ='Tray Configuration'!E24 -> Ouachita | C33: ='Picarro Output'!B247 -> P-269 | D33: =AVERAGE('Picarro Output'!F243:F247) -> -5.5342 | E33: =AVERAGE('Picarro Output'!G243:G247) -> -29.6032 | F33: 15
A34: 33 | B34: ='Tray Configuration'!F24 -> Sipsey | C34: ='Picarro Output'!B262 -> P-270 | D34: =AVERAGE('Picarro Output'!F258:F262) -> -4.5796 | E34: =AVERAGE('Picarro Output'!G258:G262) -> -22.5676 | F34: 15
A35: 34 | B35: ='Tray Configuration'!G24 -> Iceland | C35: ='Picarro Output'!B277 -> P-271 | D35: =AVERAGE('Picarro Output'!F273:F277) -> -8.0188 | E35: =AVERAGE('Picarro Output'!G273:G277) -> -52.6852 | F35: 15
A36: 35 | B36: ='Tray Configuration'!H24 -> Ouachita | C36: ='Picarro Output'!B292 -> P-272 | D36: =AVERAGE('Picarro Output'!F288:F292) -> -5.5186 | E36: =AVERAGE('Picarro Output'!G288:G292) -> -29.571 | F36: 15
A37: 36 | B37: ='Tray Configuration'!B23 -> WAIS_04M02_2_RAW_20210607 | C37: ='Picarro Output'!B298 -> P-273 | D37: =AVERAGE('Picarro Output'!F296:F298) -> -5.936 | E37: =AVERAGE('Picarro Output'!G296:G298) -> -37.019 | F37: 6
A38: 37 | B38: ='Tray Configuration'!C23 -> WAIS_04M05_2_RAW_20210607 | C38: ='Picarro Output'!B304 -> P-274 | D38: =AVERAGE('Picarro Output'!F302:F304) -> -5.923 | E38: =AVERAGE('Picarro Output'!G302:G304) -> -37.020333 | F38: 6
A39: 38 | B39: ='Tray Configuration'!D23 -> WAIS_04M09_2_RAW_20210607 | C39: ='Picarro Output'!B310 -> P-275 | D39: =AVERAGE('Picarro Output'!F308:F310) -> -6.0033333 | E39: =AVERAGE('Picarro Output'!G308:G310) -> -37.271 | F39: 6
A40: 39 | B40: ='Tray Configuration'!E23 -> WAIS_02M04_1_RAW_20210607 | C40: ='Picarro Output'!B316 -> P-276 | D40: =AVERAGE('Picarro Output'!F314:F316) -> -5.915 | E40: =AVERAGE('Picarro Output'!G314:G316) -> -36.897667 | F40: 6
...

Sheet Calibration
A1: Measured | F1: Known Values | J1: Calibration | K1: d(18_16) | M1: dD
A2: Tray Position | B2: Standard | C2: d18_16 | D2: dH | F2: ='Tray Configuration'!C33 -> Standard ID | G2: ='Tray Configuration'!D33 -> Actual d(18_16) | H2: ='Tray Configuration'!E33 -> Actual d(D_H) | J2: Standard ID | K2: measured | L2: known | M2: measured | N2: known
A3: 1 | B3: =INDEX('Uncalibrated Data'!$A$2:$E$109, Calibration!A3, 2) -> Ouachita | C3: =INDEX('Uncalibrated Data'!$A$2:$E$109, Calibration!A3, 4) -> -5.6062 | D3: =INDEX('Uncalibrated Data'!$A$2:$E$109, Calibration!A3, 5) -> -30.2202 | F3: =IF('Tray Configuration'!C34="","",'Tray Configuration'!C34) -> Iceland | G3: =IF(F3="","",'Tray Configuration'!D34) -> -8 | H3: =IF(F3="","",'Tray Configuration'!E34) -> -52.8 | J3: =IF(A3="","",B3) -> Ouachita | K3: =IF(J3="","",C3) -> -5.6062 | L3: =IF(J3="","",SUMIF($F$3:$F$18,J3,$G$3:$G$18)) -> -5.5 | M3: =IF(J3="","",D3) -> -30.2202 | N3: =IF(J3="","",SUMIF($F$3:$F$18,J3,$H$3:$H$18)) -> -29.6
A4: 2 | B4: =INDEX('Uncalibrated Data'!$A$2:$E$109, Calibration!A4, 2) -> Sipsey | C4: =INDEX('Uncalibrated Data'!$A$2:$E$109, Calibration!A4, 4) -> -4.5428 | D4: =INDEX('Uncalibrated Data'!$A$2:$E$109, Calibration!A4, 5) -> -22.9288 | F4: =IF('Tray Configuration'!C35="","",'Tray Configuration'!C35) -> Ouachita | G4: =IF(F4="","",'Tray Configuration'!D35) -> -5.5 | H4: =IF(F4="","",'Tray Configuration'!E35) -> -29.6 | J4: =IF(A4="","",B4) -> Sipsey | K4: =IF(J4="","",C4) -> -4.5428 | L4: =IF(J4="","",SUMIF($F$3:$F$18,J4,$G$3:$G$18)) -> -4.5 | M4: =IF(J4="","",D4) -> -22.9288 | N4: =IF(J4="","",SUMIF($F$3:$F$18,J4,$H$3:$H$18)) -> -22.4
A5: 3 | B5: =INDEX('Uncalibrated Data'!$A$2:$E$109, Calibration!A5, 2) -> Iceland | C5: =INDEX('Uncalibrated Data'!$A$2:$E$109, Calibration!A5, 4) -> -8.0142 | D5: =INDEX('Uncalibrated Data'!$A$2:$E$109, Calibration!A5, 5) -> -52.9894 | F5: =IF('Tray Configuration'!C36="","",'Tray Configuration'!C36) -> Sipsey | G5: =IF(F5="","",'Tray Configuration'!D36) -> -4.5 | H5: =IF(F5="","",'Tray Configuration'!E36) -> -22.4 | J5: =IF(A5="","",B5) -> Iceland | K5: =IF(J5="","",C5) -> -8.0142 | L5: =IF(J5="","",SUMIF($F$3:$F$18,J5,$G$3:$G$18)) -> -8 | M5: =IF(J5="","",D5) -> -52.9894 | N5: =IF(J5="","",SUMIF($F$3:$F$18,J5,$H$3:$H$18)) -> -52.8
A6: 4 | B6: =INDEX('Uncalibrated Data'!$A$2:$E$109, Calibration!A6, 2) -> Ouachita | C6: =INDEX('Uncalibrated Data'!$A$2:$E$109, Calibration!A6, 4) -> -5.576 | D6: =INDEX('Uncalibrated Data'!$A$2:$E$109, Calibration!A6, 5) -> -29.89 | F6: =IF('Tray Configuration'!C38="","",'Tray Configuration'!C38) | G6: =IF(F6="","",'Tray Configuration'!D38) | H6: =IF(F6="","",'Tray Configuration'!E38) | J6: =IF(A6="","",B6) -> Ouachita | K6: =IF(J6="","",C6) -> -5.576 | L6: =IF(J6="","",SUMIF($F$3:$F$18,J6,$G$3:$G$18)) -> -5.5 | M6: =IF(J6="","",D6) -> -29.89 | N6: =IF(J6="","",SUMIF($F$3:$F$18,J6,$H$3:$H$18)) -> -29.6
A7: 5 | B7: =INDEX('Uncalibrated Data'!$A$2:$E$109, Calibration!A7, 2) -> Ouachita | C7: =INDEX('Uncalibrated Data'!$A$2:$E$109, Calibration!A7, 4) -> -5.5494 | D7: =INDEX('Uncalibrated Data'!$A$2:$E$109, Calibration!A7, 5) -> -29.7474 | F7: =IF('Tray Configuration'!C39="","",'Tray Configuration'!C39) | G7: =IF(F7="","",'Tray Configuration'!D39) | H7: =IF(F7="","",'Tray Configuration'!E39) | J7: =IF(A7="","",B7) -> Ouachita | K7: =IF(J7="","",C7) -> -5.5494 | L7: =IF(J7="","",SUMIF($F$3:$F$18,J7,$G$3:$G$18)) -> -5.5 | M7: =IF(J7="","",D7) -> -29.7474 | N7: =IF(J7="","",SUMIF($F$3:$F$18,J7,$H$3:$H$18)) -> -29.6
A8: 32 | B8: =INDEX('Uncalibrated Data'!$A$2:$E$109, Calibration!A8, 2) -> Ouachita | C8: =INDEX('Uncalibrated Data'!$A$2:$E$109, Calibration!A8, 4) -> -5.5342 | D8: =INDEX('Uncalibrated Data'!$A$2:$E$109, Calibration!A8, 5) -> -29.6032 | F8: =IF('Tray Configuration'!C40="","",'Tray Configuration'!C40) | G8: =IF(F8="","",'Tray Configuration'!D40) | H8: =IF(F8="","",'Tray Configuration'!E40) | J8: =IF(A8="","",B8) -> Ouachita | K8: =IF(J8="","",C8) -> -5.5342 | L8: =IF(J8="","",SUMIF($F$3:$F$18,J8,$G$3:$G$18)) -> -5.5 | M8: =IF(J8="","",D8) -> -29.6032 | N8: =IF(J8="","",SUMIF($F$3:$F$18,J8,$H$3:$H$18)) -> -29.6
A9: 33 | B9: =INDEX('Uncalibrated Data'!$A$2:$E$109, Calibration!A9, 2) -> Sipsey | C9: =INDEX('Uncalibrated Data'!$A$2:$E$109, Calibration!A9, 4) -> -4.5796 | D9: =INDEX('Uncalibrated Data'!$A$2:$E$109, Calibration!A9, 5) -> -22.5676 | F9: =IF('Tray Configuration'!C41="","",'Tray Configuration'!C41) | G9: =IF(F9="","",'Tray Configuration'!D41) | H9: =IF(F9="","",'Tray Configuration'!E41) | J9: =IF(A9="","",B9) -> Sipsey | K9: =IF(J9="","",C9) -> -4.5796 | L9: =IF(J9="","",SUMIF($F$3:$F$18,J9,$G$3:$G$18)) -> -4.5 | M9: =IF(J9="","",D9) -> -22.5676 | N9: =IF(J9="","",SUMIF($F$3:$F$18,J9,$H$3:$H$18)) -> -22.4
A10: 34 | B10: =INDEX('Uncalibrated Data'!$A$2:$E$109, Calibration!A10, 2) -> Iceland | C10: =INDEX('Uncalibrated Data'!$A$2:$E$109, Calibration!A10, 4) -> -8.0188 | D10: =INDEX('Uncalibrated Data'!$A$2:$E$109, Calibration!A10, 5) -> -52.6852 | F10: =IF('Tray Configuration'!C42="","",'Tray Configuration'!C42) | G10: =IF(F10="","",'Tray Configuration'!D42) | H10: =IF(F10="","",'Tray Configuration'!E42) | J10: =IF(A10="","",B10) -> Iceland | K10: =IF(J10="","",C10) -> -8.0188 | L10: =IF(J10="","",SUMIF($F$3:$F$18,J10,$G$3:$G$18)) -> -8 | M10: =IF(J10="","",D10) -> -52.6852 | N10: =IF(J10="","",SUMIF($F$3:$F$18,J10,$H$3:$H$18)) -> -52.8
A11: 35 | B11: =INDEX('Uncalibrated Data'!$A$2:$E$109, Calibration!A11, 2) -> Ouachita | C11: =INDEX('Uncalibrated Data'!$A$2:$E$109, Calibration!A11, 4) -> -5.5186 | D11: =INDEX('Uncalibrated Data'!$A$2:$E$109, Calibration!A11, 5) -> -29.571 | F11: =IF('Tray Configuration'!C43="","",'Tray Configuration'!C43) | G11: =IF(F11="","",'Tray Configuration'!D43) | H11: =IF(F11="","",'Tray Configuration'!E43) | J11: =IF(A11="","",B11) -> Ouachita | K11: =IF(J11="","",C11) -> -5.5186 | L11: =IF(J11="","",SUMIF($F$3:$F$18,J11,$G$3:$G$18)) -> -5.5 | M11: =IF(J11="","",D11) -> -29.571 | N11: =IF(J11="","",SUMIF($F$3:$F$18,J11,$H$3:$H$18)) -> -29.6
A12: 67 | B12: =INDEX('Uncalibrated Data'!$A$2:$E$109, Calibration!A12, 2) -> Ouachita | C12: =INDEX('Uncalibrated Data'!$A$2:$E$109, Calibration!A12, 4) -> -5.4942 | D12: =INDEX('Uncalibrated Data'!$A$2:$E$109, Calibration!A12, 5) -> -29.343 | J12: =IF(A12="","",B12) -> Ouachita | K12: =IF(J12="","",C12) -> -5.4942 | L12: =IF(J12="","",SUMIF($F$3:$F$18,J12,$G$3:$G$18)) -> -5.5 | M12: =IF(J12="","",D12) -> -29.343 | N12: =IF(J12="","",SUMIF($F$3:$F$18,J12,$H$3:$H$18)) -> -29.6
A13: 68 | B13: =INDEX('Uncalibrated Data'!$A$2:$E$109, Calibration!A13, 2) -> Sipsey | C13: =INDEX('Uncalibrated Data'!$A$2:$E$109, Calibration!A13, 4) -> -4.5606 | D13: =INDEX('Uncalibrated Data'!$A$2:$E$109, Calibration!A13, 5) -> -22.406 | J13: =IF(A13="","",B13) -> Sipsey | K13: =IF(J13="","",C13) -> -4.5606 | L13: =IF(J13="","",SUMIF($F$3:$F$18,J13,$G$3:$G$18)) -> -4.5 | M13: =IF(J13="","",D13) -> -22.406 | N13: =IF(J13="","",SUMIF($F$3:$F$18,J13,$H$3:$H$18)) -> -22.4
A14: 69 | B14: =INDEX('Uncalibrated Data'!$A$2:$E$109, Calibration!A14, 2) -> Iceland | C14: =INDEX('Uncalibrated Data'!$A$2:$E$109, Calibration!A14, 4) -> -7.9882 | D14: =INDEX('Uncalibrated Data'!$A$2:$E$109, Calibration!A14, 5) -> -52.5476 | J14: =IF(A14="","",B14) -> Iceland | K14: =IF(J14="","",C14) -> -7.9882 | L14: =IF(J14="","",SUMIF($F$3:$F$18,J14,$G$3:$G$18)) -> -8 | M14: =IF(J14="","",D14) -> -52.5476 | N14: =IF(J14="","",SUMIF($F$3:$F$18,J14,$H$3:$H$18)) -> -52.8
A15: 70 | B15: =INDEX('Uncalibrated Data'!$A$2:$E$109, Calibration!A15, 2) -> Ouachita | C15: =INDEX('Uncalibrated Data'!$A$2:$E$109, Calibration!A15, 4) -> -5.5172 | D15: =INDEX('Uncalibrated Data'!$A$2:$E$109, Calibration!A15, 5) -> -29.4558 | J15: =IF(A15="","",B15) -> Ouachita | K15: =IF(J15="","",C15) -> -5.5172 | L15: =IF(J15="","",SUMIF($F$3:$F$18,J15,$G$3:$G$18)) -> -5.5 | M15: =IF(J15="","",D15) -> -29.4558 | N15: =IF(J15="","",SUMIF($F$3:$F$18,J15,$H$3:$H$18)) -> -29.6
A16: 102 | B16: =INDEX('Uncalibrated Data'!$A$2:$E$109, Calibration!A16, 2) -> Ouachita | C16: =INDEX('Uncalibrated Data'!$A$2:$E$109, Calibration!A16, 4) -> -5.4908 | D16: =INDEX('Uncalibrated Data'!$A$2:$E$109, Calibration!A16, 5) -> -29.3042 | J16: =IF(A16="","",B16) -> Ouachita | K16: =IF(J16="","",C16) -> -5.4908 | L16: =IF(J16="","",SUMIF($F$3:$F$18,J16,$G$3:$G$18)) -> -5.5 | M16: =IF(J16="","",D16) -> -29.3042 | N16: =IF(J16="","",SUMIF($F$3:$F$18,J16,$H$3:$H$18)) -> -29.6
A17: 103 | B17: =INDEX('Uncalibrated Data'!$A$2:$E$109, Calibration!A17, 2) -> Sipsey | C17: =INDEX('Uncalibrated Data'!$A$2:$E$109, Calibration!A17, 4) -> -4.5794 | D17: =INDEX('Uncalibrated Data'!$A$2:$E$109, Calibration!A17, 5) -> -22.3344 | J17: =IF(A17="","",B17) -> Sipsey | K17: =IF(J17="","",C17) -> -4.5794 | L17: =IF(J17="","",SUMIF($F$3:$F$18,J17,$G$3:$G$18)) -> -4.5 | M17: =IF(J17="","",D17) -> -22.3344 | N17: =IF(J17="","",SUMIF($F$3:$F$18,J17,$H$3:$H$18)) -> -22.4
A18: 104 | B18: =INDEX('Uncalibrated Data'!$A$2:$E$109, Calibration!A18, 2) -> Iceland | C18: =INDEX('Uncalibrated Data'!$A$2:$E$109, Calibration!A18, 4) -> -8.0048 | D18: =INDEX('Uncalibrated Data'!$A$2:$E$109, Calibration!A18, 5) -> -52.5378 | J18: =IF(A18="","",B18) -> Iceland | K18: =IF(J18="","",C18) -> -8.0048 | L18: =IF(J18="","",SUMIF($F$3:$F$18,J18,$G$3:$G$18)) -> -8 | M18: =IF(J18="","",D18) -> -52.5378 | N18: =IF(J18="","",SUMIF($F$3:$F$18,J18,$H$3:$H$18)) -> -52.8
A19: 105 | B19: =INDEX('Uncalibrated Data'!$A$2:$E$109, Calibration!A19, 2) -> Ouachita | C19: =INDEX('Uncalibrated Data'!$A$2:$E$109, Calibration!A19, 4) -> -5.51 | D19: =INDEX('Uncalibrated Data'!$A$2:$E$109, Calibration!A19, 5) -> -29.3946 | J19: =IF(A19="","",B19) -> Ouachita | K19: =IF(J19="","",C19) -> -5.51 | L19: =IF(J19="","",SUMIF($F$3:$F$18,J19,$G$3:$G$18)) -> -5.5 | M19: =IF(J19="","",D19) -> -29.3946 | N19: =IF(J19="","",SUMIF($F$3:$F$18,J19,$H$3:$H$18)) -> -29.6
A22: Calibration Results
A23: CALIBRATION 1
B24: d(18_16) | C24: dD
A25: Slope | B25: =IF(A3="",1,SLOPE(L3:L11,K3:K11)) -> 1.013571 | C25: =IF(A3="",0,SLOPE(N3:N11,M3:M11)) -> 1.008789
A26: Intercept | B26: =IF(A3="",1,INTERCEPT(L3:L11,K3:K11)) -> 0.12869387 | C26: =IF(A3="",0,INTERCEPT(N3:N11,M3:M11)) -> 0.49347632
A27: R^2 | B27: =RSQ(L3:L11,K3:K11) -> 0.99956868 | C27: =RSQ(N3:N11,M3:M11) -> 0.99961922
A28: CALIBRATION 2
B29: d(18_16) | C29: dD
A30: Slope | B30: =IF(A8="",1,SLOPE(L12:L15,K12:K15)) -> 1.0169271 | C30: =IF(A8="",0,SLOPE(N12:N15,M12:M15)) -> 1.0062804
A31: Intercept | B31: =IF(A8="",1,INTERCEPT(L12:L15,K12:K15)) -> 0.1147512 | C31: =IF(A8="",0,INTERCEPT(N12:N15,M12:M15)) -> 0.048105873
A32: R^2 | B32: =RSQ(L12:L15,K12:K15) -> 0.99979326 | C32: =RSQ(N12:N15,M12:M15) -> 0.99995201
A33: CALIBRATION 3
B34: d(18_16) | C34: dD
A35: Slope | B35: =IF(A13="",1,SLOPE(L16:L19,K16:K19)) -> 1.0145633 | C35: =IF(A13="",0,SLOPE(N16:N19,M16:M19)) -> 1.0043407
A36: Intercept | B36: =IF(A13="",1,INTERCEPT(L16:L19,K16:K19)) -> 0.107119 | C36: =IF(A13="",0,INTERCEPT(N16:N19,M16:M19)) -> -0.062300622
A37: R^2 | B37: =RSQ(L16:L19,K16:K19) -> 0.99950227 | C37: =RSQ(N16:N19,M16:M19) -> 0.99995989

Sheet QAQC + Calibrated Data
A1: ='Uncalibrated Data'!B1 -> Sample ID | B1: ='Uncalibrated Data'!D1 -> d(18_16) | C1: ='Uncalibrated Data'!E1 -> d(D_H) | F1: QC | I1: PASS? | L1: d18_16 | O1: dD
A2: ='Uncalibrated Data'!B2 -> Ouachita | B2: =IF('Uncalibrated Data'!D2="","",Calibration!$B$25*'Uncalibrated Data'!D2+Calibration!$B$26) -> -5.5535877 | C2: =IF('Uncalibrated Data'!E2="","",Calibration!$C$25*'Uncalibrated Data'!E2+Calibration!$C$26) -> -29.992329 | F2: Sample ID | G2: d(18_16) | H2: d(D_H) | I2: YES/NO | L2: 0.1 | M2: Actual | N2: -0.1 | O2: 0.1 | P2: Actual | Q2: -0.1
A3: ='Uncalibrated Data'!B3 -> Sipsey | B3: =IF('Uncalibrated Data'!D3="","",Calibration!$B$25*'Uncalibrated Data'!D3+Calibration!$B$26) -> -4.4757564 | C3: =IF('Uncalibrated Data'!E3="","",Calibration!$C$25*'Uncalibrated Data'!E3+Calibration!$C$26) -> -22.636845 | F3: =A6 -> Ouachita | G3: =B6 -> -5.4960169 | H3: =C6 -> -29.515374 | I3: =IF(AND($L$3 <=G3, G3<= $N$3, $O$3<=H3, H3<=$Q$3),"YES","NO") -> YES | K3: OUACHITA | L3: =M3*1.1 -> -6.05 | M3: ='Tray Configuration'!D35 -> -5.5 | N3: =M3*0.9 -> -4.95 | O3: =P3*1.1 -> -32.56 | P3: ='Tray Configuration'!E35 -> -29.6 | Q3: =P3*0.9 -> -26.64
A4: ='Uncalibrated Data'!B4 -> Iceland | B4: =IF('Uncalibrated Data'!D4="","",Calibration!$B$25*'Uncalibrated Data'!D4+Calibration!$B$26) -> -7.9942667 | C4: =IF('Uncalibrated Data'!E4="","",Calibration!$C$25*'Uncalibrated Data'!E4+Calibration!$C$26) -> -52.961648 | F4: =A15 -> Ouachita | G4: =B15 -> -5.4831108 | H4: =C15 -> -29.503201 | I4: =IF(AND($L$3 <=G4, G4<= $N$3, $O$3<=H4, H4<=$Q$3),"YES","NO") -> YES
A5: ='Uncalibrated Data'!B5 -> Ouachita | B5: =IF('Uncalibrated Data'!D5="","",Calibration!$B$25*'Uncalibrated Data'!D5+Calibration!$B$26) -> -5.5229779 | C5: =IF('Uncalibrated Data'!E5="","",Calibration!$C$25*'Uncalibrated Data'!E5+Calibration!$C$26) -> -29.659227 | F5: =A22 -> Ouachita | G5: =B22 -> -5.4800701 | H5: =C22 -> -29.435276 | I5: =IF(AND($L$3 <=G5, G5<= $N$3, $O$3<=H5, H5<=$Q$3),"YES","NO") -> YES
A6: ='Uncalibrated Data'!B6 -> Ouachita | B6: =IF('Uncalibrated Data'!D6="","",Calibration!$B$25*'Uncalibrated Data'!D6+Calibration!$B$26) -> -5.4960169 | C6: =IF('Uncalibrated Data'!E6="","",Calibration!$C$25*'Uncalibrated Data'!E6+Calibration!$C$26) -> -29.515374 | F6: =A29 -> Ouachita | G6: =B29 -> -5.4733129 | H6: =C29 -> -29.488069 | I6: =IF(AND($L$3 <=G6, G6<= $N$3, $O$3<=H6, H6<=$Q$3),"YES","NO") -> YES
A7: ='Uncalibrated Data'!B7 -> WAIS_SFM01_2_RAW_20210607 | B7: =IF('Uncalibrated Data'!D7="","",Calibration!$B$25*'Uncalibrated Data'!D7+Calibration!$B$26) -> -5.8898906 | C7: =IF('Uncalibrated Data'!E7="","",Calibration!$C$25*'Uncalibrated Data'!E7+Calibration!$C$26) -> -36.759757 | F7: =A36 -> Ouachita | G7: =B36 -> -5.4647989 | H7: =C36 -> -29.337424 | I7: =IF(AND($L$3 <=G7, G7<= $N$3, $O$3<=H7, H7<=$Q$3),"YES","NO") -> YES
A8: ='Uncalibrated Data'!B8 -> WAIS_SFM02_1_RAW_20210607 | B8: =IF('Uncalibrated Data'!D8="","",Calibration!$B$25*'Uncalibrated Data'!D8+Calibration!$B$26) -> -5.9111756 | C8: =IF('Uncalibrated Data'!E8="","",Calibration!$C$25*'Uncalibrated Data'!E8+Calibration!$C$26) -> -36.911412 | F8: =A43 -> Ouachita | G8: =B43 -> -5.3390286 | H8: =C43 -> -29.676412 | I8: =IF(AND($L$3 <=G8, G8<= $N$3, $O$3<=H8, H8<=$Q$3),"YES","NO") -> YES
A9: ='Uncalibrated Data'!B9 -> WAIS_SFM03_1_RAW_20210607 | B9: =IF('Uncalibrated Data'!D9="","",Calibration!$B$25*'Uncalibrated Data'!D9+Calibration!$B$26) -> -5.8891023 | C9: =IF('Uncalibrated Data'!E9="","",Calibration!$C$25*'Uncalibrated Data'!E9+Calibration!$C$26) -> -36.820621 | F9: =A50 -> Ouachita | G9: =B50 -> -5.4691953 | H9: =C50 -> -29.590543 | I9: =IF(AND($L$3 <=G9, G9<= $N$3, $O$3<=H9, H9<=$Q$3),"YES","NO") -> YES
A10: ='Uncalibrated Data'!B10 -> WAIS_SFM04_1_RAW_20210607 | B10: =IF('Uncalibrated Data'!D10="","",Calibration!$B$25*'Uncalibrated Data'!D10+Calibration!$B$26) -> -5.884147 | C10: =IF('Uncalibrated Data'!E10="","",Calibration!$C$25*'Uncalibrated Data'!E10+Calibration!$C$26) -> -36.898297 | F10: =A57 -> Ouachita | G10: =B57 -> -5.4763137 | H10: =C57 -> -29.554987 | I10: =IF(AND($L$3 <=G10, G10<= $N$3, $O$3<=H10, H10<=$Q$3),"YES","NO") -> YES
A11: ='Uncalibrated Data'!B11 -> WAIS_SFM05_1_RAW_20210607 | B11: =IF('Uncalibrated Data'!D11="","",Calibration!$B$25*'Uncalibrated Data'!D11+Calibration!$B$26) -> -5.867592 | C11: =IF('Uncalibrated Data'!E11="","",Calibration!$C$25*'Uncalibrated Data'!E11+Calibration!$C$26) -> -36.76581 | F11: =A64 -> Ouachita | G11: =B64 -> -5.4756358 | H11: =C64 -> -29.591549 | I11: =IF(AND($L$3 <=G11, G11<= $N$3, $O$3<=H11, H11<=$Q$3),"YES","NO") -> YES
A12: ='Uncalibrated Data'!B12 -> WAIS_SFM06_1_RAW_20210607 | B12: =IF('Uncalibrated Data'!D12="","",Calibration!$B$25*'Uncalibrated Data'!D12+Calibration!$B$26) -> -5.8844849 | C12: =IF('Uncalibrated Data'!E12="","",Calibration!$C$25*'Uncalibrated Data'!E12+Calibration!$C$26) -> -36.795065 | F12: =A71 -> Ouachita | G12: =B71 -> -5.4958387 | H12: =C71 -> -29.592689 | I12: =IF(AND($L$3 <=G12, G12<= $N$3, $O$3<=H12, H12<=$Q$3),"YES","NO") -> YES
A13: ='Uncalibrated Data'!B13 -> WAIS_SFM07_1_RAW_20210607 | B13: =IF('Uncalibrated Data'!D13="","",Calibration!$B$25*'Uncalibrated Data'!D13+Calibration!$B$26) -> -5.9317849 | C13: =IF('Uncalibrated Data'!E13="","",Calibration!$C$25*'Uncalibrated Data'!E13+Calibration!$C$26) -> -37.002203 | F13: =A78 -> Ouachita | G13: =B78 -> -5.4469388 | H13: =C78 -> -29.592932 | I13: =IF(AND($L$3 <=G13, G13<= $N$3, $O$3<=H13, H13<=$Q$3),"YES","NO") -> YES
A14: ='Uncalibrated Data'!B14 -> WAIS_SFT01_1_RAW_20210606 | B14: =IF('Uncalibrated Data'!D14="","",Calibration!$B$25*'Uncalibrated Data'!D14+Calibration!$B$26) -> -5.7648835 | C14: =IF('Uncalibrated Data'!E14="","",Calibration!$C$25*'Uncalibrated Data'!E14+Calibration!$C$26) -> -36.555645 | F14: =A85 -> Ouachita | G14: =B85 -> -5.4604663 | H14: =C85 -> -29.559453 | I14: =IF(AND($L$3 <=G14, G14<= $N$3, $O$3<=H14, H14<=$Q$3),"YES","NO") -> YES
A15: ='Uncalibrated Data'!B15 -> Ouachita | B15: =IF('Uncalibrated Data'!D15="","",Calibration!$B$25*'Uncalibrated Data'!D15+Calibration!$B$26) -> -5.4831108 | C15: =IF('Uncalibrated Data'!E15="","",Calibration!$C$25*'Uncalibrated Data'!E15+Calibration!$C$26) -> -29.503201 | F15: =A92 -> Ouachita | G15: =B92 -> -5.4641864 | H15: =C92 -> -29.401772 | I15: =IF(AND($L$3 <=G15, G15<= $N$3, $O$3<=H15, H15<=$Q$3),"YES","NO") -> YES
A16: ='Uncalibrated Data'!B16 -> WAIS_SFT02_1_RAW_20210606 | B16: =IF('Uncalibrated Data'!D16="","",Calibration!$B$25*'Uncalibrated Data'!D16+Calibration!$B$26) -> -5.848672 | C16: =IF('Uncalibrated Data'!E16="","",Calibration!$C$25*'Uncalibrated Data'!E16+Calibration!$C$26) -> -36.979673 | F16: =A99 -> Ouachita | G16: =B99 -> -5.4712883 | H16: =C99 -> -29.564475 | I16: =IF(AND($L$3 <=G16, G16<= $N$3, $O$3<=H16, H16<=$Q$3),"YES","NO") -> YES
A17: ='Uncalibrated Data'!B17 -> WAIS_01M01_1_RAW_20210607 | B17: =IF('Uncalibrated Data'!D17="","",Calibration!$B$25*'Uncalibrated Data'!D17+Calibration!$B$26) -> -5.9260413 | C17: =IF('Uncalibrated Data'!E17="","",Calibration!$C$25*'Uncalibrated Data'!E17+Calibration!$C$26) -> -37.167644 | F17: =A106 -> Ouachita | G17: =B106 -> -5.4831249 | H17: =C106 -> -29.584495 | I17: =IF(AND($L$3 <=G17, G17<= $N$3, $O$3<=H17, H17<=$Q$3),"YES","NO") -> YES
A18: ='Uncalibrated Data'!B18 -> WAIS_01M02_1_RAW_20210607 | B18: =IF('Uncalibrated Data'!D18="","",Calibration!$B$25*'Uncalibrated Data'!D18+Calibration!$B$26) -> -5.9422584 | C18: =IF('Uncalibrated Data'!E18="","",Calibration!$C$25*'Uncalibrated Data'!E18+Calibration!$C$26) -> -37.211022
A19: ='Uncalibrated Data'!B19 -> WAIS_01M03_1_RAW_20210607 | B19: =IF('Uncalibrated Data'!D19="","",Calibration!$B$25*'Uncalibrated Data'!D19+Calibration!$B$26) -> -5.7510314 | C19: =IF('Uncalibrated Data'!E19="","",Calibration!$C$25*'Uncalibrated Data'!E19+Calibration!$C$26) -> -36.409707
A20: ='Uncalibrated Data'!B20 -> WAIS_01M04_1_RAW_20210607 | B20: =IF('Uncalibrated Data'!D20="","",Calibration!$B$25*'Uncalibrated Data'!D20+Calibration!$B$26) -> -5.7858306 | C20: =IF('Uncalibrated Data'!E20="","",Calibration!$C$25*'Uncalibrated Data'!E20+Calibration!$C$26) -> -36.58759
A21: ='Uncalibrated Data'!B21 -> WAIS_01M05_1_RAW_20210607 | B21: =IF('Uncalibrated Data'!D21="","",Calibration!$B$25*'Uncalibrated Data'!D21+Calibration!$B$26) -> -5.8142106 | C21: =IF('Uncalibrated Data'!E21="","",Calibration!$C$25*'Uncalibrated Data'!E21+Calibration!$C$26) -> -36.794728 | E21: Run # | F21: Extra Replicate Comparisons | I21: d(18_16) | J21: d(D_H)
A22: ='Uncalibrated Data'!B22 -> Ouachita | B22: =IF('Uncalibrated Data'!D22="","",Calibration!$B$25*'Uncalibrated Data'!D22+Calibration!$B$26) -> -5.4800701 | C22: =IF('Uncalibrated Data'!E22="","",Calibration!$C$25*'Uncalibrated Data'!E22+Calibration!$C$26) -> -29.435276 | E22: 1 | F22: WAIS_SFM01_1_RAW_672021 | I22: -6.0011978 | J22: -39.085678
A23: ='Uncalibrated Data'!B23 -> WAIS_01M06_1_RAW_20210607 | B23: =IF('Uncalibrated Data'!D23="","",Calibration!$B$25*'Uncalibrated Data'!D23+Calibration!$B$26) -> -5.7658971 | C23: =IF('Uncalibrated Data'!E23="","",Calibration!$C$25*'Uncalibrated Data'!E23+Calibration!$C$26) -> -36.396257 | E23: 2 | F23: WAIS_SFM01_2_RAW_20210607 | I23: -5.8898906 | J23: -36.759757
A24: ='Uncalibrated Data'!B24 -> WAIS_20M04_1_RAW_20210607 | B24: =IF('Uncalibrated Data'!D24="","",Calibration!$B$25*'Uncalibrated Data'!D24+Calibration!$B$26) -> -5.9807741 | C24: =IF('Uncalibrated Data'!E24="","",Calibration!$C$25*'Uncalibrated Data'!E24+Calibration!$C$26) -> -36.985726 | E24: 1 | F24: WAIS_04M02_1_RAW_672021 | I24: -5.9918366 | J24: -38.758385
A25: ='Uncalibrated Data'!B25 -> WAIS_20M05_1_RAW_20210607 | B25: =IF('Uncalibrated Data'!D25="","",Calibration!$B$25*'Uncalibrated Data'!D25+Calibration!$B$26) -> -6.0115191 | C25: =IF('Uncalibrated Data'!E25="","",Calibration!$C$25*'Uncalibrated Data'!E25+Calibration!$C$26) -> -37.313582 | E25: 2 | F25: WAIS_04M02_2_RAW_20210607 | I25: -5.9217278 | J25: -37.20339
A26: ='Uncalibrated Data'!B26 -> WAIS_02M01_1_RAW_20210607 | B26: =IF('Uncalibrated Data'!D26="","",Calibration!$B$25*'Uncalibrated Data'!D26+Calibration!$B$26) -> -5.7827899 | C26: =IF('Uncalibrated Data'!E26="","",Calibration!$C$25*'Uncalibrated Data'!E26+Calibration!$C$26) -> -36.420131 | E26: 1 | F26: WAIS_04M05_1_RAW_672021 | I26: -5.9440274 | J26: -37.726179
A27: ='Uncalibrated Data'!B27 -> WAIS_02M02_1_RAW_20210607 | B27: =IF('Uncalibrated Data'!D27="","",Calibration!$B$25*'Uncalibrated Data'!D27+Calibration!$B$26) -> -5.8044128 | C27: =IF('Uncalibrated Data'!E27="","",Calibration!$C$25*'Uncalibrated Data'!E27+Calibration!$C$26) -> -36.55161 | E27: 2 | F27: WAIS_04M05_2_RAW_20210607 | I27: -5.9085077 | J27: -37.204731
A28: ='Uncalibrated Data'!B28 -> WAIS_02M03_1_RAW_20210607 | B28: =IF('Uncalibrated Data'!D28="","",Calibration!$B$25*'Uncalibrated Data'!D28+Calibration!$B$26) -> -5.8331306 | C28: =IF('Uncalibrated Data'!E28="","",Calibration!$C$25*'Uncalibrated Data'!E28+Calibration!$C$26) -> -36.581201 | E28: 1 | F28: WAIS_04M09_1_RAW_672021 | I28: -5.9707738 | J28: -37.462545
A29: ='Uncalibrated Data'!B29 -> Ouachita | B29: =IF('Uncalibrated Data'!D29="","",Calibration!$B$25*'Uncalibrated Data'!D29+Calibration!$B$26) -> -5.4733129 | C29: =IF('Uncalibrated Data'!E29="","",Calibration!$C$25*'Uncalibrated Data'!E29+Calibration!$C$26) -> -29.488069 | E29: 2 | F29: WAIS_04M09_2_RAW_20210607 | I29: -5.9902009 | J29: -37.456972
A30: ='Uncalibrated Data'!B30 -> WAIS_02M05_1_RAW_20210607_spring | B30: =IF('Uncalibrated Data'!D30="","",Calibration!$B$25*'Uncalibrated Data'!D30+Calibration!$B$26) -> -5.8145485 | C30: =IF('Uncalibrated Data'!E30="","",Calibration!$C$25*'Uncalibrated Data'!E30+Calibration!$C$26) -> -36.811541
A31: ='Uncalibrated Data'!B31 -> WAIS_02M06_1_RAW_20210607 | B31: =IF('Uncalibrated Data'!D31="","",Calibration!$B$25*'Uncalibrated Data'!D31+Calibration!$B$26) -> -5.898337 | C31: =IF('Uncalibrated Data'!E31="","",Calibration!$C$25*'Uncalibrated Data'!E31+Calibration!$C$26) -> -36.874759
A32: ='Uncalibrated Data'!B32 -> WAIS_02M07_1_RAW_20210607 | B32: =IF('Uncalibrated Data'!D32="","",Calibration!$B$25*'Uncalibrated Data'!D32+Calibration!$B$26) -> -5.9023913 | C32: =IF('Uncalibrated Data'!E32="","",Calibration!$C$25*'Uncalibrated Data'!E32+Calibration!$C$26) -> -36.992451
A33: ='Uncalibrated Data'!B33 -> Ouachita | B33: =IF('Uncalibrated Data'!D33="","",Calibration!$B$25*'Uncalibrated Data'!D33+Calibration!$B$26) -> -5.4806106 | C33: =IF('Uncalibrated Data'!E33="","",Calibration!$C$25*'Uncalibrated Data'!E33+Calibration!$C$26) -> -29.369907
A34: ='Uncalibrated Data'!B34 -> Sipsey | B34: =IF('Uncalibrated Data'!D34="","",Calibration!$B$25*'Uncalibrated Data'!D34+Calibration!$B$26) -> -4.5130558 | C34: =IF('Uncalibrated Data'!E34="","",Calibration!$C$25*'Uncalibrated Data'!E34+Calibration!$C$26) -> -22.272471
A35: ='Uncalibrated Data'!B35 -> Iceland | B35: =IF('Uncalibrated Data'!D35="","",Calibration!$B$25*'Uncalibrated Data'!D35+Calibration!$B$26) -> -7.9989291 | C35: =IF('Uncalibrated Data'!E35="","",Calibration!$C$25*'Uncalibrated Data'!E35+Calibration!$C$26) -> -52.654775
A36: ='Uncalibrated Data'!B36 -> Ouachita | B36: =IF('Uncalibrated Data'!D36="","",Calibration!$B$25*'Uncalibrated Data'!D36+Calibration!$B$26) -> -5.4647989 | C36: =IF('Uncalibrated Data'!E36="","",Calibration!$C$25*'Uncalibrated Data'!E36+Calibration!$C$26) -> -29.337424
A37: ='Uncalibrated Data'!B37 -> WAIS_04M02_2_RAW_20210607 | B37: =IF('Uncalibrated Data'!D37="","",Calibration!$B$30*'Uncalibrated Data'!D37+Calibration!$B$31) -> -5.9217278 | C37: =IF('Uncalibrated Data'!E37="","",Calibration!$C$30*'Uncalibrated Data'!E37+Calibration!$C$31) -> -37.20339
A38: ='Uncalibrated Data'!B38 -> WAIS_04M05_2_RAW_20210607 | B38: =IF('Uncalibrated Data'!D38="","",Calibration!$B$30*'Uncalibrated Data'!D38+Calibration!$B$31) -> -5.9085077 | C38: =IF('Uncalibrated Data'!E38="","",Calibration!$C$30*'Uncalibrated Data'!E38+Calibration!$C$31) -> -37.204731
A39: ='Uncalibrated Data'!B39 -> WAIS_04M09_2_RAW_20210607 | B39: =IF('Uncalibrated Data'!D39="","",Calibration!$B$30*'Uncalibrated Data'!D39+Calibration!$B$31) -> -5.9902009 | C39: =IF('Uncalibrated Data'!E39="","",Calibration!$C$30*'Uncalibrated Data'!E39+Calibration!$C$31) -> -37.456972
A40: ='Uncalibrated Data'!B40 -> WAIS_02M04_1_RAW_20210607 | B40: =IF('Uncalibrated Data'!D40="","",Calibration!$B$30*'Uncalibrated Data'!D40+Calibration!$B$31) -> -5.9003723 | C40: =IF('Uncalibrated Data'!E40="","",Calibration!$C$30*'Uncalibrated Data'!E40+Calibration!$C$31) -> -37.081294
...

Sheet Data Export
A1: Sample ID | B1: d(18_16) | C1: d(D_H)
A2: WAIS_SFM01_2_RAW_20210607 | B2: -5.8898906 | C2: -36.759757
A3: WAIS_SFM02_1_RAW_20210607 | B3: -5.9111756 | C3: -36.911412
A4: WAIS_SFM03_1_RAW_20210607 | B4: -5.8891023 | C4: -36.820621
A5: WAIS_SFM04_1_RAW_20210607 | B5: -5.884147 | C5: -36.898297
A6: WAIS_SFM05_1_RAW_20210607 | B6: -5.867592 | C6: -36.76581
A7: WAIS_SFM06_1_RAW_20210607 | B7: -5.8844849 | C7: -36.795065
A8: WAIS_SFM07_1_RAW_20210607 | B8: -5.9317849 | C8: -37.002203
A9: WAIS_SFT01_1_RAW_20210606 | B9: -5.7648835 | C9: -36.555645
A10: WAIS_SFT02_1_RAW_20210606 | B10: -5.848672 | C10: -36.979673
A11: WAIS_01M01_1_RAW_20210607 | B11: -5.9260413 | C11: -37.167644
A12: WAIS_01M02_1_RAW_20210607 | B12: -5.9422584 | C12: -37.211022
A13: WAIS_01M03_1_RAW_20210607 | B13: -5.7510314 | C13: -36.409707
... A77: WAIS_04W04_1_RAW_20210809 | B77: -5.8422803 | C77: -36.788363
