Workbook

Sheet Instructions

Sheet Tray Configuration
B2: Operator Name | D2: AMG + DMP | J2: Run Start Time
B3: Sampling Loaction | D3: Konza, Talladega, Weyerhaeuser, Paint Rock | J3: 44655.642
B4: Sampling Date | D4: Summer 2021, fall-spring 2022
B5: Project | D5: AIMS
B6: Notes | D6: changed injection port septa prior to run
B12: TRAY
A14: 99
A15: 92 | I15: 14
A16: 85 | B16: PRA01 20220314 | C16: PRM19 20220314 | D16: WAIS_02M09_1_RAW_NODATE | I16: 13
A17: 78 | B17: PRM01 20220112 | C17: PRM01 20220314 | D17: PRM06 20220314 | E17: PRB01 20220314 | F17: PRM11 20220314 | G17: PRM15 20220314 | H17: Ouachita | I17: 12
A18: 71 | B18: WHM10 20220322 | C18: WHM12 20220322 | D18: PRM01 20211013 | E18: PRM01 20211103 | F18: PRM01 20211122 | G18: PRM01 20211215 | H18: Ouachita | I18: 11
A19: 64 | B19: WHA02 20220322 | C19: WHM03 20220322 | D19: WHM07 20220322 | E19: Ouachita | F19: Sipsey | G19: Iceland | H19: Ouachita | I19: 10
A20: 57 | B20: WHM01 20211104 | C20: WHM01 20211129 | D20: WHM01 20211220 | E20: WHM01 20220106 | F20: WHM01 20220322 | G20: WHB01 20220322 | H20: Ouachita | I20: 9
A21: 50 | B21: TLM10 20220330 | C21: TLA01 20220330 | D21: TLM16 20220330 | E21: TLM19 20220330 | F21: TAL Precip 20220330 | G21: WHM01 20211014 | H21: Ouachita | I21: 8
A22: 43 | B22: TLA01 20220124 | C22: TLM16 20220124 | D22: TLM19 20220124 | E22: TLM01 20220330 | F22: TLC01 20220330 | G22: TLM06 20220330 | H22: Ouachita | I22: 7
A23: 36 | B23: TLM01 20220131 | C23: TLP01 20220124 | D23: TLM01 20220124 | E23: TLC01 20220124 | F23: TLM10 20220124 | G23: TLM06 20220124 | H23: Ouachita | I23: 6
A24: 29 | B24: TLM01 20211026 | C24: TLM01 20211110 | D24: TLM01 20220105 | E24: Ouachita | F24: Sipsey | G24: Iceland | H24: Ouachita | I24: 5
A25: 22 | B25: 3_5_MOR_N4D_DUP_20220113 | C25: WAIS_ENM03_1_RAW_20210811 | D25: WAIS_ENM01_1_RAW_20210916 | E25: WAIS_SFM01_1_RAW_20210903 | F25: WAIS_ENM03_1_RAW_20211015 | G25: TLM01 20211007 | H25: Ouachita | I25: 4
A26: 15 | B26: WAIS_N2BSeepB_RAW_20220211 | C26: WAIS_33Eis_1_Filt_20220113 | D26: WAIS_ENM01_1_RAW_20211123 | E26: WAIS_ENM03_1_RAW_20210827 | F26: 4_6_MOR_DUP_N4D_20220113 | G26: 4_6_Eis2_DUP_20220113 | H26: Ouachita | I26: 3
A27: 8 | B27: WAIS_02M07_2_RAW_20210809 | C27: WAIS_SFM01_1_RAW_20211214 | D27: WAIS_N01B_1_RAW_20210903 | E27: WAIS_N4DWSeep1_RAW_20220211 | F27: WAIS_N4DWSeep2_RAW_20220211 | G27: WAIS_N4DSeep4_RAW_20220211 | H27: Ouachita | I27: 2
A28: 1 | B28: Ouachita | C28: Sipsey | D28: Iceland | E28: Sipsey | F28: Ouachita | G28: WAIS_01M01_2_RAW_20210809 | H28: WAIS_02M06_2_RAW_20210809
B29: 1 | C29: 2 | D29: 3 | E29: 4 | F29: 5 | G29: 6 | H29: 7
B32: Standards
C33: Standard ID | D33: Actual d(18_16) | E33: Actual d(D_H)
B34: #1 | C34: Iceland | D34: -8 | E34: -52.8
B35: #2 | C35: Ouachita | D35: -5.5 | E35: -29.6
B36: #3 | C36: Sipsey | D36: -4.5 | E36: -22.4
B37: #4 | C37: Ivishak | D37: -22 | E37: -168.7
B38: #5
B39: #6
B40: #7
B41: #8
B42: #9
B43: #10
B44: #11
B45: #12

Sheet Timing
A1: Enter start time and date --> | C1: 44655.635
A2: Tray Position | B2: Sample ID | C2: Start Time | D2: # Injections
A3: 1 | B3: ='Tray Configuration'!B28 -> Ouachita | C3: =C1 -> 44655.635 | D3: 15
A4: 2 | B4: ='Tray Configuration'!C28 -> Sipsey | C4: =C3+"0:08:57"*D3 -> 44655.729 | D4: 15
A5: 3 | B5: ='Tray Configuration'!D28 -> Iceland | C5: =C4+"0:08:57"*D4 -> 44655.822 | D5: 15
A6: 4 | B6: ='Tray Configuration'!E28 -> Sipsey | C6: =C5+"0:08:57"*D5 -> 44655.915 | D6: 15
A7: 5 | B7: ='Tray Configuration'!F28 -> Ouachita | C7: =C6+"0:08:57"*D6 -> 44656.008 | D7: 15
A8: 6 | B8: ='Tray Configuration'!G28 -> WAIS_01M01_2_RAW_20210809 | C8: =C7+"0:08:57"*D7 -> 44656.102 | D8: 6
A9: 7 | B9: ='Tray Configuration'!H28 -> WAIS_02M06_2_RAW_20210809 | C9: =C8+"0:08:57"*D8 -> 44656.139 | D9: 6
A10: 8 | B10: ='Tray Configuration'!B27 -> WAIS_02M07_2_RAW_20210809 | C10: =C9+"0:08:57"*D9 -> 44656.176 | D10: 6
A11: 9 | B11: ='Tray Configuration'!C27 -> WAIS_SFM01_1_RAW_20211214 | C11: =C10+"0:08:57"*D10 -> 44656.213 | D11: 6
A12: 10 | B12: ='Tray Configuration'!D27 -> WAIS_N01B_1_RAW_20210903 | C12: =C11+"0:08:57"*D11 -> 44656.251 | D12: 6
A13: 11 | B13: ='Tray Configuration'!E27 -> WAIS_N4DWSeep1_RAW_20220211 | C13: =C12+"0:08:57"*D12 -> 44656.288 | D13: 6
A14: 12 | B14: ='Tray Configuration'!F27 -> WAIS_N4DWSeep2_RAW_20220211 | C14: =C13+"0:08:57"*D13 -> 44656.325 | D14: 6
A15: 13 | B15: ='Tray Configuration'!G27 -> WAIS_N4DSeep4_RAW_20220211 | C15: =C14+"0:08:57"*D14 -> 44656.363 | D15: 6
A16: 14 | B16: ='Tray Configuration'!H27 -> Ouachita | C16: =C15+"0:08:57"*D15 -> 44656.4 | D16: 6
A17: 15 | B17: ='Tray Configuration'!B26 -> WAIS_N2BSeepB_RAW_20220211 | C17: =C16+"0:08:57"*D16 -> 44656.437 | D17: 6
A18: 16 | B18: ='Tray Configuration'!C26 -> WAIS_33Eis_1_Filt_20220113 | C18: =C17+"0:08:57"*D17 -> 44656.474 | D18: 6
A19: 17 | B19: ='Tray Configuration'!D26 -> WAIS_ENM01_1_RAW_20211123 | C19: =C18+"0:08:57"*D18 -> 44656.512 | D19: 6
A20: 18 | B20: ='Tray Configuration'!E26 -> WAIS_ENM03_1_RAW_20210827 | C20: =C19+"0:08:57"*D19 -> 44656.549 | D20: 6
A21: 19 | B21: ='Tray Configuration'!F26 -> 4_6_MOR_DUP_N4D_20220113 | C21: =C20+"0:08:57"*D20 -> 44656.586 | D21: 6
A22: 20 | B22: ='Tray Configuration'!G26 -> 4_6_Eis2_DUP_20220113 | C22: =C21+"0:08:57"*D21 -> 44656.624 | D22: 6
A23: 21 | B23: ='Tray Configuration'!H26 -> Ouachita | C23: =C22+"0:08:57"*D22 -> 44656.661 | D23: 6
A24: 22 | B24: ='Tray Configuration'!B25 -> 3_5_MOR_N4D_DUP_20220113 | C24: =C23+"0:08:57"*D23 -> 44656.698 | D24: 6
A25: 23 | B25: ='Tray Configuration'!C25 -> WAIS_ENM03_1_RAW_20210811 | C25: =C24+"0:08:57"*D24 -> 44656.736 | D25: 6
A26: 24 | B26: ='Tray Configuration'!D25 -> WAIS_ENM01_1_RAW_20210916 | C26: =C25+"0:08:57"*D25 -> 44656.773 | D26: 6
A27: 25 | B27: ='Tray Configuration'!E26 -> WAIS_ENM03_1_RAW_20210827 | C27: =C26+"0:08:57"*D26 -> 44656.81 | D27: 6
A28: 26 | B28: ='Tray Configuration'!F25 -> WAIS_ENM03_1_RAW_20211015 | C28: =C27+"0:08:57"*D27 -> 44656.847 | D28: 6
A29: 27 | B29: ='Tray Configuration'!G25 -> TLM01 20211007 | C29: =C28+"0:08:57"*D28 -> 44656.885 | D29: 6
A30: 28 | B30: ='Tray Configuration'!H25 -> Ouachita | C30: =C29+"0:08:57"*D29 -> 44656.922 | D30: 6
A31: 29 | B31: ='Tray Configuration'!B24 -> TLM01 20211026 | C31: =C30+"0:08:57"*D30 -> 44656.959 | D31: 6
A32: 30 | B32: ='Tray Configuration'!C24 -> TLM01 20211110 | C32: =C31+"0:08:57"*D31 -> 44656.997 | D32: 6
A33: 31 | B33: ='Tray Configuration'!D24 -> TLM01 20220105 | C33: =C32+"0:08:57"*D32 -> 44657.034 | D33: 6
A34: 32 | B34: ='Tray Configuration'!E24 -> Ouachita | C34: =C33+"0:08:57"*D33 -> 44657.071 | D34: 15
A35: 33 | B35: ='Tray Configuration'!F24 -> Sipsey | C35: =C34+"0:08:57"*D34 -> 44657.164 | D35: 15
A36: 34 | B36: ='Tray Configuration'!G24 -> Iceland | C36: =C35+"0:08:57"*D35 -> 44657.258 | D36: 15
A37: 35 | B37: ='Tray Configuration'!H24 -> Ouachita | C37: =C36+"0:08:57"*D36 -> 44657.351 | D37: 15
A38: 36 | B38: ='Tray Configuration'!B23 -> TLM01 20220131 | C38: =C37+"0:08:57"*D37 -> 44657.444 | D38: 6
A39: 37 | B39: ='Tray Configuration'!C23 -> TLP01 20220124 | C39: =C38+"0:08:57"*D38 -> 44657.481 | D39: 6
A40: 38 | B40: ='Tray Configuration'!D23 -> TLM01 20220124 | C40: =C39+"0:08:57"*D39 -> 44657.519 | D40: 6
...

Sheet Picarro Output
A1: Line | B1: Analysis | C1: Time Code | D1: Port | E1: Inj Nr | F1: d(18_16)Mean | G1: d(D_H)Mean | H1: H2O_Mean | I1: Ignore | J1: Good | K1: Identifier 1 | L1: Identifier 2 | M1: Gas Configuration | N1: Timestamp Mean | O1: d(18_16)_SD | P1: d(D_H)_SD | Q1: H2O_SD | R1: d(18_16)_Sl | S1: d(D_H)_Sl | T1: H2O_Sl | U1: baseline_shift | V1: slope_shift | W1: residuals | X1: baseline_curvature | Y1: interval | Z1: ch4_ppm | AA1: h16od_adjust | AB1: h16od_shift | AC1: n2_flag | AD1: DAS Temp | AE1: Tray | AF1: Sample | AG1: Job | AH1: Method | AI1: Error Code
A2: 1 | B2: P-1058 | C2: 2022/04/04 15:25:20 | D2: 1-01 | E2: 1 | F2: -6.009 | G2: -36.838 | H2: 16744 | I2: -1 | J2: 1 | M2: H2O | N2: 1.6491042e+09 | O2: 0.201 | P2: 0.419 | Q2: 60.643 | R2: 0 | S2: -0.005 | T2: 1.459 | U2: 98.876 | V2: 21.047 | W2: 2.424 | X2: 92.625 | Y2: 1.038 | Z2: 0.431 | AA2: 0 | AB2: 0 | AC2: 1 | AD2: 39.938 | AE2: 1 | AF2: 1 | AG2: 1 | AH2: Ecohydro | AI2: 0
A3: 2 | B3: P-1058 | C3: 2022/04/04 15:34:18 | D3: 1-01 | E3: 2 | F3: -5.674 | G3: -32.225 | H3: 16948 | I3: -1 | J3: 1 | M3: H2O | N3: 1.6491048e+09 | O3: 0.197 | P3: 0.459 | Q3: 58.254 | R3: 0 | S3: -0.005 | T3: 1.39 | U3: 100.186 | V3: 20.969 | W3: 2.386 | X3: 93.209 | Y3: 1.048 | Z3: 0.233 | AA3: 0 | AB3: 0 | AC3: 1 | AD3: 39.938 | AE3: 1 | AF3: 1 | AG3: 1 | AH3: Ecohydro | AI3: 0
A4: 3 | B4: P-1058 | C4: 2022/04/04 15:43:15 | D4: 1-01 | E4: 3 | F4: -5.615 | G4: -31.273 | H4: 17158 | I4: -1 | J4: 1 | M4: H2O | N4: 1.6491053e+09 | O4: 0.202 | P4: 0.416 | Q4: 57.277 | R4: 0 | S4: -0.004 | T4: 1.366 | U4: 101.806 | V4: 20.615 | W4: 2.405 | X4: 94.274 | Y4: 1.042 | Z4: 0.148 | AA4: 0 | AB4: 0 | AC4: 1 | AD4: 39.938 | AE4: 1 | AF4: 1 | AG4: 1 | AH4: Ecohydro | AI4: 0
A5: 4 | B5: P-1058 | C5: 2022/04/04 15:52:13 | D5: 1-01 | E5: 4 | F5: -5.64 | G5: -30.836 | H5: 17118 | I5: 0 | J5: 1 | M5: H2O | N5: 1.6491058e+09 | O5: 0.186 | P5: 0.401 | Q5: 57.819 | R5: 0.001 | S5: -0.003 | T5: 1.391 | U5: 101.484 | V5: 20.791 | W5: 2.365 | X5: 93.397 | Y5: 1.02 | Z5: 0.177 | AA5: 0 | AB5: 0 | AC5: 1 | AD5: 39.938 | AE5: 1 | AF5: 1 | AG5: 1 | AH5: Ecohydro | AI5: 0
A6: 5 | B6: P-1058 | C6: 2022/04/04 16:01:11 | D6: 1-01 | E6: 5 | F6: -5.636 | G6: -30.678 | H6: 17115 | I6: 0 | J6: 1 | M6: H2O | N6: 1.6491064e+09 | O6: 0.203 | P6: 0.352 | Q6: 60.052 | R6: 0 | S6: -0.003 | T6: 1.42 | U6: 101.168 | V6: 20.759 | W6: 2.449 | X6: 95.07 | Y6: 1.06 | Z6: 0.422 | AA6: 0 | AB6: 0 | AC6: 1 | AD6: 39.938 | AE6: 1 | AF6: 1 | AG6: 1 | AH6: Ecohydro | AI6: 0
A7: 6 | B7: P-1058 | C7: 2022/04/04 16:10:08 | D7: 1-01 | E7: 6 | F7: -5.555 | G7: -30.37 | H7: 17092 | I7: 0 | J7: 1 | M7: H2O | N7: 1.6491069e+09 | O7: 0.189 | P7: 0.37 | Q7: 57.527 | R7: 0.001 | S7: -0.003 | T7: 1.385 | U7: 101.286 | V7: 20.881 | W7: 2.342 | X7: 93.169 | Y7: 1.032 | Z7: 0.087 | AA7: 0 | AB7: 0 | AC7: 1 | AD7: 40 | AE7: 1 | AF7: 1 | AG7: 1 | AH7: Ecohydro | AI7: 0
A8: 7 | B8: P-1058 | C8: 2022/04/04 16:19:06 | D8: 1-01 | E8: 7 | F8: -5.563 | G8: -30.376 | H8: 17065 | I8: 0 | J8: 1 | M8: H2O | N8: 1.6491075e+09 | O8: 0.214 | P8: 0.395 | Q8: 59.29 | R8: 0 | S8: -0.003 | T8: 1.421 | U8: 100.854 | V8: 20.992 | W8: 2.371 | X8: 93.759 | Y8: 1.033 | Z8: 0.29 | AA8: 0 | AB8: 0 | AC8: 1 | AD8: 40 | AE8: 1 | AF8: 1 | AG8: 1 | AH8: Ecohydro | AI8: 0
A9: 8 | B9: P-1058 | C9: 2022/04/04 16:28:04 | D9: 1-01 | E9: 8 | F9: -5.52 | G9: -30.179 | H9: 17125 | I9: 0 | J9: 1 | M9: H2O | N9: 1.649108e+09 | O9: 0.204 | P9: 0.449 | Q9: 59.444 | R9: 0.001 | S9: -0.001 | T9: 1.433 | U9: 101.694 | V9: 20.029 | W9: 2.406 | X9: 94.684 | Y9: 0.989 | Z9: 0.224 | AA9: 0 | AB9: 0 | AC9: 1 | AD9: 40.062 | AE9: 1 | AF9: 1 | AG9: 1 | AH9: Ecohydro | AI9: 0
A10: 9 | B10: P-1058 | C10: 2022/04/04 16:37:01 | D10: 1-01 | E10: 9 | F10: -5.571 | G10: -30.05 | H10: 17152 | I10: 0 | J10: 1 | M10: H2O | N10: 1.6491085e+09 | O10: 0.194 | P10: 0.396 | Q10: 59.049 | R10: 0.001 | S10: -0.001 | T10: 1.412 | U10: 101.497 | V10: 20.861 | W10: 2.422 | X10: 94.221 | Y10: 0.988 | Z10: 0.242 | AA10: 0 | AB10: 0 | AC10: 1 | AD10: 40.125 | AE10: 1 | AF10: 1 | AG10: 1 | AH10: Ecohydro | AI10: 0
A11: 10 | B11: P-1058 | C11: 2022/04/04 16:45:59 | D11: 1-01 | E11: 10 | F11: -5.521 | G11: -30.094 | H11: 17072 | I11: 0 | J11: 1 | M11: H2O | N11: 1.6491091e+09 | O11: 0.198 | P11: 0.363 | Q11: 58.227 | R11: 0 | S11: -0.001 | T11: 1.402 | U11: 101.232 | V11: 20.638 | W11: 2.365 | X11: 93.098 | Y11: 0.984 | Z11: 0.033 | AA11: 0 | AB11: 0 | AC11: 1 | AD11: 40.125 | AE11: 1 | AF11: 1 | AG11: 1 | AH11: Ecohydro | AI11: 0
A12: 11 | B12: P-1058 | C12: 2022/04/04 16:54:57 | D12: 1-01 | E12: 11 | F12: -5.524 | G12: -29.97 | H12: 17084 | I12: 0 | J12: 1 | M12: H2O | N12: 1.6491096e+09 | O12: 0.218 | P12: 0.372 | Q12: 59.728 | R12: 0 | S12: -0.003 | T12: 1.435 | U12: 100.959 | V12: 20.773 | W12: 2.418 | X12: 94.711 | Y12: 0.987 | Z12: 0.392 | AA12: 0 | AB12: 0 | AC12: 1 | AD12: 40.125 | AE12: 1 | AF12: 1 | AG12: 1 | AH12: Ecohydro | AI12: 0
A13: 12 | B13: P-1058 | C13: 2022/04/04 17:03:54 | D13: 1-01 | E13: 12 | F13: -5.521 | G13: -29.905 | H13: 17076 | I13: 0 | J13: 1 | M13: H2O | N13: 1.6491101e+09 | O13: 0.17 | P13: 0.356 | Q13: 58.434 | R13: 0.001 | S13: -0.001 | T13: 1.403 | U13: 101.152 | V13: 21.253 | W13: 2.343 | X13: 91.655 | Y13: 0.967 | Z13: -0.097 | AA13: 0 | AB13: 0 | AC13: 1 | AD13: 40.062 | AE13: 1 | AF13: 1 | AG13: 1 | AH13: Ecohydro | AI13: 0
... A640: 639 | B640: P-1144 | C640: 2022/04/08 14:39:51 | D640: 1-87 | E640: 6 | F640: -5.838 | G640: -36.381 | H640: 17098 | I640: 0 | J640: 1 | M640: H2O | N640: 1.6494471e+09 | O640: 0.206 | P640: 0.356 | Q640: 55.056 | R640: 0.001 | S640: 0.001 | T640: 1.311 | U640: 101.071 | V640: 21.638 | W640: 2.394 | X640: 92.767 | Y640: 0.901 | Z640: 0.265 | AA640: 0 | AB640: 0 | AC640: 1 | AD640: 40.188 | AE640: 1 | AF640: 87 | AG640: 6 | AH640: Ecohydro | AI640: 0

Sheet Uncalibrated Data
A1: Tray Position | B1: Sample ID | C1: Picarro ID | D1: d(18_16) | E1: d(D_H) | F1: Count
A2: 1 | B2: ='Tray Configuration'!B28 -> Ouachita | C2: ='Picarro Output'!B16 -> P-1058 | D2: =AVERAGE('Picarro Output'!F12:F16) -> -5.5098 | E2: =AVERAGE('Picarro Output'!G12:G16) -> -29.8414 | F2: 15
A3: 2 | B3: ='Tray Configuration'!C28 -> Sipsey | C3: ='Picarro Output'!B31 -> P-1059 | D3: =AVERAGE('Picarro Output'!F27:F31) -> -4.5478 | E3: =AVERAGE('Picarro Output'!G27:G31) -> -22.6564 | F3: 15
A4: 3 | B4: ='Tray Configuration'!D28 -> Iceland | C4: ='Picarro Output'!B46 -> P-1060 | D4: =AVERAGE('Picarro Output'!F42:F46) -> -7.9614 | E4: =AVERAGE('Picarro Output'!G42:G46) -> -52.7198 | F4: 15
A5: 4 | B5: ='Tray Configuration'!E28 -> Sipsey | C5: ='Picarro Output'!B61 -> P-1061 | D5: =AVERAGE('Picarro Output'!F57:F61) -> -4.4944 | E5: =AVERAGE('Picarro Output'!G57:G61) -> -22.4934 | F5: 15
A6: 5 | B6: ='Tray Configuration'!F28 -> Ouachita | C6: ='Picarro Output'!B76 -> P-1062 | D6: =AVERAGE('Picarro Output'!F72:F76) -> -5.4786 | E6: =AVERAGE('Picarro Output'!G72:G76) -> -29.4128 | F6: 15
A7: 6 | B7: ='Tray Configuration'!G28 -> WAIS_01M01_2_RAW_20210809 | C7: ='Picarro Output'!B82 -> P-1063 | D7: =AVERAGE('Picarro Output'!F80:F82) -> 0.096333333 | E7: =AVERAGE('Picarro Output'!G80:G82) -> 2.3436667 | F7: 6
A8: 7 | B8: ='Tray Configuration'!H28 -> WAIS_02M06_2_RAW_20210809 | C8: ='Picarro Output'!B88 -> P-1064 | D8: =AVERAGE('Picarro Output'!F86:F88) -> -1.4983333 | E8: =AVERAGE('Picarro Output'!G86:G88) -> -11.952667 | F8: 6
A9: 8 | B9: ='Tray Configuration'!B27 -> WAIS_02M07_2_RAW_20210809 | C9: ='Picarro Output'!B94 -> P-1065 | D9: =AVERAGE('Picarro Output'!F84:F92) -> -1.9201111 | E9: =AVERAGE('Picarro Output'!G92:G94) -> -17.767333 | F9: 6
A10: 9 | B10: ='Tray Configuration'!C27 -> WAIS_SFM01_1_RAW_20211214 | C10: ='Picarro Output'!B100 -> P-1066 | D10: =AVERAGE('Picarro Output'!F98:F100) -> -5.659 | E10: =AVERAGE('Picarro Output'!G98:G100) -> -35.33 | F10: 6
A11: 10 | B11: ='Tray Configuration'!D27 -> WAIS_N01B_1_RAW_20210903 | C11: ='Picarro Output'!B106 -> P-1067 | D11: =AVERAGE('Picarro Output'!F104:F106) -> -5.39 | E11: =AVERAGE('Picarro Output'!G104:G106) -> -29.235 | F11: 6
A12: 11 | B12: ='Tray Configuration'!E27 -> WAIS_N4DWSeep1_RAW_20220211 | C12: ='Picarro Output'!B112 -> P-1068 | D12: =AVERAGE('Picarro Output'!F110:F112) -> -6.1496667 | E12: =AVERAGE('Picarro Output'!G110:G112) -> -38.88 | F12: 6
A13: 12 | B13: ='Tray Configuration'!F27 -> WAIS_N4DWSeep2_RAW_20220211 | C13: ='Picarro Output'!B118 -> P-1069 | D13: =AVERAGE('Picarro Output'!F116:F118) -> -6.199 | E13: =AVERAGE('Picarro Output'!G116:G118) -> -39.243333 | F13: 6
A14: 13 | B14: ='Tray Configuration'!G27 -> WAIS_N4DSeep4_RAW_20220211 | C14: ='Picarro Output'!B124 -> P-1070 | D14: =AVERAGE('Picarro Output'!F122:F124) -> -6.045 | E14: =AVERAGE('Picarro Output'!G122:G124) -> -38.401667 | F14: 6
A15: 14 | B15: ='Tray Configuration'!H27 -> Ouachita | C15: ='Picarro Output'!B130 -> P-1071 | D15: =AVERAGE('Picarro Output'!F128:F130) -> -5.367 | E15: =AVERAGE('Picarro Output'!G128:G130) -> -29.377667 | F15: 6
A16: 15 | B16: ='Tray Configuration'!B26 -> WAIS_N2BSeepB_RAW_20220211 | C16: ='Picarro Output'!B136 -> P-1072 | D16: =AVERAGE('Picarro Output'!F134:F136) -> -6.069 | E16: =AVERAGE('Picarro Output'!G134:G136) -> -38.318333 | F16: 6
A17: 16 | B17: ='Tray Configuration'!C26 -> WAIS_33Eis_1_Filt_20220113 | C17: ='Picarro Output'!B142 -> P-1073 | D17: =AVERAGE('Picarro Output'!F140:F142) -> -5.727 | E17: =AVERAGE('Picarro Output'!G140:G142) -> -36.811667 | F17: 6
A18: 17 | B18: ='Tray Configuration'!D26 -> WAIS_ENM01_1_RAW_20211123 | C18: ='Picarro Output'!B148 -> P-1074 | D18: =AVERAGE('Picarro Output'!F146:F148) -> -4.897 | E18: =AVERAGE('Picarro Output'!G146:G148) -> -30.022 | F18: 6
A19: 18 | B19: ='Tray Configuration'!E26 -> WAIS_ENM03_1_RAW_20210827 | C19: ='Picarro Output'!B154 -> P-1075 | D19: =AVERAGE('Picarro Output'!F152:F154) -> -3.8876667 | E19: =AVERAGE('Picarro Output'!G152:G154) -> -23.865333 | F19: 6
A20: 19 | B20: ='Tray Configuration'!F26 -> 4_6_MOR_DUP_N4D_20220113 | C20: ='Picarro Output'!B160 -> P-1076 | D20: =AVERAGE('Picarro Output'!F158:F160) -> -5.8666667 | E20: =AVERAGE('Picarro Output'!G158:G160) -> -36.765667 | F20: 6
A21: 20 | B21: ='Tray Configuration'!G26 -> 4_6_Eis2_DUP_20220113 | C21: ='Picarro Output'!B166 -> P-1077 | D21: =AVERAGE('Picarro Output'!F164:F166) -> -5.9243333 | E21: =AVERAGE('Picarro Output'!G164:G166) -> -37.528333 | F21: 6
A22: 21 | B22: ='Tray Configuration'!H26 -> Ouachita | C22: ='Picarro Output'!B172 -> P-1078 | D22: =AVERAGE('Picarro Output'!F170:F172) -> -5.5066667 | E22: =AVERAGE('Picarro Output'!G170:G172) -> -29.450667 | F22: 6
A23: 22 | B23: ='Tray Configuration'!B25 -> 3_5_MOR_N4D_DUP_20220113 | C23: ='Picarro Output'!B178 -> P-1079 | D23: =AVERAGE('Picarro Output'!F176:F178) -> -5.8706667 | E23: =AVERAGE('Picarro Output'!G176:G178) -> -36.850667 | F23: 6
A24: 23 | B24: ='Tray Configuration'!C25 -> WAIS_ENM03_1_RAW_20210811 | C24: ='Picarro Output'!B184 -> P-1080 | D24: =AVERAGE('Picarro Output'!F182:F184) -> -4.0453333 | E24: =AVERAGE('Picarro Output'!G182:G184) -> -24.997667 | F24: 6
A25: 24 | B25: ='Tray Configuration'!D25 -> WAIS_ENM01_1_RAW_20210916 | C25: ='Picarro Output'!B190 -> P-1081 | D25: =AVERAGE('Picarro Output'!F188:F190) -> -4.71 | E25: =AVERAGE('Picarro Output'!G188:G190) -> -28.803 | F25: 6
A26: 25 | B26: ='Tray Configuration'!F25 -> WAIS_ENM03_1_RAW_20211015 | C26: ='Picarro Output'!B196 -> P-1082 | D26: =AVERAGE('Picarro Output'!F194:F196) -> -5.672 | E26: =AVERAGE('Picarro Output'!G194:G196) -> -29.429333 | F26: 6
A27: 26 | B27: ='Tray Configuration'!F25 -> WAIS_ENM03_1_RAW_20211015 | C27: ='Picarro Output'!B202 -> P-1083 | D27: =AVERAGE('Picarro Output'!F200:F202) -> -4.9546667 | E27: =AVERAGE('Picarro Output'!G200:G202) -> -29.941667 | F27: 6
A28: 27 | B28: ='Tray Configuration'!G25 -> TLM01 20211007 | C28: ='Picarro Output'!B208 -> P-1084 | D28: =AVERAGE('Picarro Output'!F206:F208) -> -4.7986667 | E28: =AVERAGE('Picarro Output'!G206:G208) -> -24.470667 | F28: 6
A29: 28 | B29: ='Tray Configuration'!H25 -> Ouachita | C29: ='Picarro Output'!B214 -> P-1085 | D29: =AVERAGE('Picarro Output'!F212:F214) -> -5.5083333 | E29: =AVERAGE('Picarro Output'!G212:G214) -> -29.378667 | F29: 6
A30: 29 | B30: ='Tray Configuration'!B24 -> TLM01 20211026 | C30: ='Picarro Output'!B220 -> P-1086 | D30: =AVERAGE('Picarro Output'!F218:F220) -> -4.7836667 | E30: =AVERAGE('Picarro Output'!G218:G220) -> -24.601667 | F30: 6
A31: 30 | B31: ='Tray Configuration'!C24 -> TLM01 20211110 | C31: ='Picarro Output'!B226 -> P-1087 | D31: =AVERAGE('Picarro Output'!F224:F226) -> -4.8023333 | E31: =AVERAGE('Picarro Output'!G224:G226) -> -24.64 | F31: 6
A32: 31 | B32: ='Tray Configuration'!D24 -> TLM01 20220105 | C32: ='Picarro Output'!B232 -> P-1088 | D32: =AVERAGE('Picarro Output'!F230:F232) -> -4.529 | E32: =AVERAGE('Picarro Output'!G230:G232) -> -22.129333 | F32: 6
A33: 32 | B33: ='Tray Configuration'!E24 -> Ouachita | C33: ='Picarro Output'!B247 -> P-1089 | D33: =AVERAGE('Picarro Output'!F243:F247) -> -5.4642 | E33: =AVERAGE('Picarro Output'!G243:G247) -> -29.2228 | F33: 15
A34: 33 | B34: ='Tray Configuration'!F24 -> Sipsey | C34: ='Picarro Output'!B262 -> P-1090 | D34: =AVERAGE('Picarro Output'!F258:F262) -> -4.5336 | E34: =AVERAGE('Picarro Output'!G258:G262) -> -22.3218 | F34: 15
A35: 34 | B35: ='Tray Configuration'!G24 -> Iceland | C35: ='Picarro Output'!B277 -> P-1091 | D35: =AVERAGE('Picarro Output'!F273:F277) -> -7.9722 | E35: =AVERAGE('Picarro Output'!G273:G277) -> -52.4126 | F35: 15
A36: 35 | B36: ='Tray Configuration'!H24 -> Ouachita | C36: ='Picarro Output'!B292 -> P-1092 | D36: =AVERAGE('Picarro Output'!F288:F292) -> -5.4994 | E36: =AVERAGE('Picarro Output'!G288:G292) -> -29.3316 | F36: 15
A37: 36 | B37: ='Tray Configuration'!B23 -> TLM01 20220131 | C37: ='Picarro Output'!B298 -> P-1093 | D37: =AVERAGE('Picarro Output'!F296:F298) -> -4.7673333 | E37: =AVERAGE('Picarro Output'!G296:G298) -> -24.172333 | F37: 6
A38: 37 | B38: ='Tray Configuration'!C23 -> TLP01 20220124 | C38: ='Picarro Output'!B304 -> P-1094 | D38: =AVERAGE('Picarro Output'!F302:F304) -> -4.765 | E38: =AVERAGE('Picarro Output'!G302:G304) -> -24.102 | F38: 6
A39: 38 | B39: ='Tray Configuration'!D23 -> TLM01 20220124 | C39: ='Picarro Output'!B310 -> P-1095 | D39: =AVERAGE('Picarro Output'!F308:F310) -> -4.7193333 | E39: =AVERAGE('Picarro Output'!G308:G310) -> -23.710667 | F39: 6
A40: 39 | B40: ='Tray Configuration'!E23 -> TLC01 20220124 | C40: ='Picarro Output'!B316 -> P-1096 | D40: =AVERAGE('Picarro Output'!F314:F316) -> -4.7416667 | E40: =AVERAGE('Picarro Output'!G314:G316) -> -23.921 | F40: 6
...

Sheet Calibration
A1: Measured | F1: Known Values | J1: Calibration | K1: d(18_16) | M1: dD
A2: Tray Position | B2: Standard | C2: d18_16 | D2: dH | F2: ='Tray Configuration'!C33 -> Standard ID | G2: ='Tray Configuration'!D33 -> Actual d(18_16) | H2: ='Tray Configuration'!E33 -> Actual d(D_H) | J2: Standard ID | K2: measured | L2: known | M2: measured | N2: known
A3: 1 | B3: =INDEX('Uncalibrated Data'!$A$2:$E$109, Calibration!A3, 2) -> Ouachita | C3: =INDEX('Uncalibrated Data'!$A$2:$E$109, Calibration!A3, 4) -> -5.5098 | D3: =INDEX('Uncalibrated Data'!$A$2:$E$109, Calibration!A3, 5) -> -29.8414 | F3: =IF('Tray Configuration'!C34="","",'Tray Configuration'!C34) -> Iceland | G3: =IF(F3="","",'Tray Configuration'!D34) -> -8 | H3: =IF(F3="","",'Tray Configuration'!E34) -> -52.8 | J3: =IF(A3="","",B3) -> Ouachita | K3: =IF(J3="","",C3) -> -5.5098 | L3: =IF(J3="","",SUMIF($F$3:$F$18,J3,$G$3:$G$18)) -> -5.5 | M3: =IF(J3="","",D3) -> -29.8414 | N3: =IF(J3="","",SUMIF($F$3:$F$18,J3,$H$3:$H$18)) -> -29.6
A4: 2 | B4: =INDEX('Uncalibrated Data'!$A$2:$E$109, Calibration!A4, 2) -> Sipsey | C4: =INDEX('Uncalibrated Data'!$A$2:$E$109, Calibration!A4, 4) -> -4.5478 | D4: =INDEX('Uncalibrated Data'!$A$2:$E$109, Calibration!A4, 5) -> -22.6564 | F4: =IF('Tray Configuration'!C35="","",'Tray Configuration'!C35) -> Ouachita | G4: =IF(F4="","",'Tray Configuration'!D35) -> -5.5 | H4: =IF(F4="","",'Tray Configuration'!E35) -> -29.6 | J4: =IF(A4="","",B4) -> Sipsey | K4: =IF(J4="","",C4) -> -4.5478 | L4: =IF(J4="","",SUMIF($F$3:$F$18,J4,$G$3:$G$18)) -> -4.5 | M4: =IF(J4="","",D4) -> -22.6564 | N4: =IF(J4="","",SUMIF($F$3:$F$18,J4,$H$3:$H$18)) -> -22.4
A5: 3 | B5: =INDEX('Uncalibrated Data'!$A$2:$E$109, Calibration!A5, 2) -> Iceland | C5: =INDEX('Uncalibrated Data'!$A$2:$E$109, Calibration!A5, 4) -> -7.9614 | D5: =INDEX('Uncalibrated Data'!$A$2:$E$109, Calibration!A5, 5) -> -52.7198 | F5: =IF('Tray Configuration'!C36="","",'Tray Configuration'!C36) -> Sipsey | G5: =IF(F5="","",'Tray Configuration'!D36) -> -4.5 | H5: =IF(F5="","",'Tray Configuration'!E36) -> -22.4 | J5: =IF(A5="","",B5) -> Iceland | K5: =IF(J5="","",C5) -> -7.9614 | L5: =IF(J5="","",SUMIF($F$3:$F$18,J5,$G$3:$G$18)) -> -8 | M5: =IF(J5="","",D5) -> -52.7198 | N5: =IF(J5="","",SUMIF($F$3:$F$18,J5,$H$3:$H$18)) -> -52.8
A6: 4 | B6: =INDEX('Uncalibrated Data'!$A$2:$E$109, Calibration!A6, 2) -> Sipsey | C6: =INDEX('Uncalibrated Data'!$A$2:$E$109, Calibration!A6, 4) -> -4.4944 | D6: =INDEX('Uncalibrated Data'!$A$2:$E$109, Calibration!A6, 5) -> -22.4934 | F6: =IF('Tray Configuration'!C38="","",'Tray Configuration'!C38) | G6: =IF(F6="","",'Tray Configuration'!D38) | H6: =IF(F6="","",'Tray Configuration'!E38) | J6: =IF(A6="","",B6) -> Sipsey | K6: =IF(J6="","",C6) -> -4.4944 | L6: =IF(J6="","",SUMIF($F$3:$F$18,J6,$G$3:$G$18)) -> -4.5 | M6: =IF(J6="","",D6) -> -22.4934 | N6: =IF(J6="","",SUMIF($F$3:$F$18,J6,$H$3:$H$18)) -> -22.4
A7: 5 | B7: =INDEX('Uncalibrated Data'!$A$2:$E$109, Calibration!A7, 2) -> Ouachita | C7: =INDEX('Uncalibrated Data'!$A$2:$E$109, Calibration!A7, 4) -> -5.4786 | D7: =INDEX('Uncalibrated Data'!$A$2:$E$109, Calibration!A7, 5) -> -29.4128 | F7: =IF('Tray Configuration'!C39="","",'Tray Configuration'!C39) | G7: =IF(F7="","",'Tray Configuration'!D39) | H7: =IF(F7="","",'Tray Configuration'!E39) | J7: =IF(A7="","",B7) -> Ouachita | K7: =IF(J7="","",C7) -> -5.4786 | L7: =IF(J7="","",SUMIF($F$3:$F$18,J7,$G$3:$G$18)) -> -5.5 | M7: =IF(J7="","",D7) -> -29.4128 | N7: =IF(J7="","",SUMIF($F$3:$F$18,J7,$H$3:$H$18)) -> -29.6
A8: 32 | B8: =INDEX('Uncalibrated Data'!$A$2:$E$109, Calibration!A8, 2) -> Ouachita | C8: =INDEX('Uncalibrated Data'!$A$2:$E$109, Calibration!A8, 4) -> -5.4642 | D8: =INDEX('Uncalibrated Data'!$A$2:$E$109, Calibration!A8, 5) -> -29.2228 | F8: =IF('Tray Configuration'!C40="","",'Tray Configuration'!C40) | G8: =IF(F8="","",'Tray Configuration'!D40) | H8: =IF(F8="","",'Tray Configuration'!E40) | J8: =IF(A8="","",B8) -> Ouachita | K8: =IF(J8="","",C8) -> -5.4642 | L8: =IF(J8="","",SUMIF($F$3:$F$18,J8,$G$3:$G$18)) -> -5.5 | M8: =IF(J8="","",D8) -> -29.2228 | N8: =IF(J8="","",SUMIF($F$3:$F$18,J8,$H$3:$H$18)) -> -29.6
A9: 33 | B9: =INDEX('Uncalibrated Data'!$A$2:$E$109, Calibration!A9, 2) -> Sipsey | C9: =INDEX('Uncalibrated Data'!$A$2:$E$109, Calibration!A9, 4) -> -4.5336 | D9: =INDEX('Uncalibrated Data'!$A$2:$E$109, Calibration!A9, 5) -> -22.3218 | F9: =IF('Tray Configuration'!C41="","",'Tray Configuration'!C41) | G9: =IF(F9="","",'Tray Configuration'!D41) | H9: =IF(F9="","",'Tray Configuration'!E41) | J9: =IF(A9="","",B9) -> Sipsey | K9: =IF(J9="","",C9) -> -4.5336 | L9: =IF(J9="","",SUMIF($F$3:$F$18,J9,$G$3:$G$18)) -> -4.5 | M9: =IF(J9="","",D9) -> -22.3218 | N9: =IF(J9="","",SUMIF($F$3:$F$18,J9,$H$3:$H$18)) -> -22.4
A10: 34 | B10: =INDEX('Uncalibrated Data'!$A$2:$E$109, Calibration!A10, 2) -> Iceland | C10: =INDEX('Uncalibrated Data'!$A$2:$E$109, Calibration!A10, 4) -> -7.9722 | D10: =INDEX('Uncalibrated Data'!$A$2:$E$109, Calibration!A10, 5) -> -52.4126 | F10: =IF('Tray Configuration'!C42="","",'Tray Configuration'!C42) | G10: =IF(F10="","",'Tray Configuration'!D42) | H10: =IF(F10="","",'Tray Configuration'!E42) | J10: =IF(A10="","",B10) -> Iceland | K10: =IF(J10="","",C10) -> -7.9722 | L10: =IF(J10="","",SUMIF($F$3:$F$18,J10,$G$3:$G$18)) -> -8 | M10: =IF(J10="","",D10) -> -52.4126 | N10: =IF(J10="","",SUMIF($F$3:$F$18,J10,$H$3:$H$18)) -> -52.8
A11: 35 | B11: =INDEX('Uncalibrated Data'!$A$2:$E$109, Calibration!A11, 2) -> Ouachita | C11: =INDEX('Uncalibrated Data'!$A$2:$E$109, Calibration!A11, 4) -> -5.4994 | D11: =INDEX('Uncalibrated Data'!$A$2:$E$109, Calibration!A11, 5) -> -29.3316 | J11: =IF(A11="","",B11) -> Ouachita | K11: =IF(J11="","",C11) -> -5.4994 | L11: =IF(J11="","",SUMIF($F$3:$F$18,J11,$G$3:$G$18)) -> -5.5 | M11: =IF(J11="","",D11) -> -29.3316 | N11: =IF(J11="","",SUMIF($F$3:$F$18,J11,$H$3:$H$18)) -> -29.6
A12: 67 | B12: =INDEX('Uncalibrated Data'!$A$2:$E$109, Calibration!A12, 2) -> Ouachita | C12: =INDEX('Uncalibrated Data'!$A$2:$E$109, Calibration!A12, 4) -> -5.395 | D12: =INDEX('Uncalibrated Data'!$A$2:$E$109, Calibration!A12, 5) -> -28.8694 | J12: =IF(A12="","",B12) -> Ouachita | K12: =IF(J12="","",C12) -> -5.395 | L12: =IF(J12="","",SUMIF($F$3:$F$18,J12,$G$3:$G$18)) -> -5.5 | M12: =IF(J12="","",D12) -> -28.8694 | N12: =IF(J12="","",SUMIF($F$3:$F$18,J12,$H$3:$H$18)) -> -29.6
A13: 68 | B13: =INDEX('Uncalibrated Data'!$A$2:$E$109, Calibration!A13, 2) -> Sipsey | C13: =INDEX('Uncalibrated Data'!$A$2:$E$109, Calibration!A13, 4) -> -4.481 | D13: =INDEX('Uncalibrated Data'!$A$2:$E$109, Calibration!A13, 5) -> -22.0198 | J13: =IF(A13="","",B13) -> Sipsey | K13: =IF(J13="","",C13) -> -4.481 | L13: =IF(J13="","",SUMIF($F$3:$F$18,J13,$G$3:$G$18)) -> -4.5 | M13: =IF(J13="","",D13) -> -22.0198 | N13: =IF(J13="","",SUMIF($F$3:$F$18,J13,$H$3:$H$18)) -> -22.4
A14: 69 | B14: =INDEX('Uncalibrated Data'!$A$2:$E$109, Calibration!A14, 2) -> Iceland | C14: =INDEX('Uncalibrated Data'!$A$2:$E$109, Calibration!A14, 4) -> -7.9144 | D14: =INDEX('Uncalibrated Data'!$A$2:$E$109, Calibration!A14, 5) -> -52.2148 | J14: =IF(A14="","",B14) -> Iceland | K14: =IF(J14="","",C14) -> -7.9144 | L14: =IF(J14="","",SUMIF($F$3:$F$18,J14,$G$3:$G$18)) -> -8 | M14: =IF(J14="","",D14) -> -52.2148 | N14: =IF(J14="","",SUMIF($F$3:$F$18,J14,$H$3:$H$18)) -> -52.8
A15: 70 | B15: =INDEX('Uncalibrated Data'!$A$2:$E$109, Calibration!A15, 2) -> Ouachita | C15: =INDEX('Uncalibrated Data'!$A$2:$E$109, Calibration!A15, 4) -> -5.4144 | D15: =INDEX('Uncalibrated Data'!$A$2:$E$109, Calibration!A15, 5) -> -29.0038 | F15: =IF('Tray Configuration'!C43="","",'Tray Configuration'!C43) | G15: =IF(F15="","",'Tray Configuration'!D43) | H15: =IF(F15="","",'Tray Configuration'!E43) | J15: =IF(A15="","",B15) -> Ouachita | K15: =IF(J15="","",C15) -> -5.4144 | L15: =IF(J15="","",SUMIF($F$3:$F$18,J15,$G$3:$G$18)) -> -5.5 | M15: =IF(J15="","",D15) -> -29.0038 | N15: =IF(J15="","",SUMIF($F$3:$F$18,J15,$H$3:$H$18)) -> -29.6
A16: 102 | B16: =INDEX('Uncalibrated Data'!$A$2:$E$109, Calibration!A16, 2) -> 0 | C16: =INDEX('Uncalibrated Data'!$A$2:$E$109, Calibration!A16, 4) -> #DIV/0! | D16: =INDEX('Uncalibrated Data'!$A$2:$E$109, Calibration!A16, 5) -> #DIV/0! | F16: =IF('Tray Configuration'!C44="","",'Tray Configuration'!C44) | G16: =IF(F16="","",'Tray Configuration'!D44) | H16: =IF(F16="","",'Tray Configuration'!E44) | J16: =IF(A16="","",B16) -> 0 | K16: =IF(J16="","",C16) -> #DIV/0! | L16: =IF(J16="","",SUMIF($F$3:$F$18,J16,$G$3:$G$18)) -> 0 | M16: =IF(J16="","",D16) -> #DIV/0! | N16: =IF(J16="","",SUMIF($F$3:$F$18,J16,$H$3:$H$18)) -> 0
A17: 103 | B17: =INDEX('Uncalibrated Data'!$A$2:$E$109, Calibration!A17, 2) -> 0 | C17: =INDEX('Uncalibrated Data'!$A$2:$E$109, Calibration!A17, 4) -> #DIV/0! | D17: =INDEX('Uncalibrated Data'!$A$2:$E$109, Calibration!A17, 5) -> #DIV/0! | F17: =IF('Tray Configuration'!C45="","",'Tray Configuration'!C45) | G17: =IF(F17="","",'Tray Configuration'!D45) | H17: =IF(F17="","",'Tray Configuration'!E45) | J17: =IF(A17="","",B17) -> 0 | K17: =IF(J17="","",C17) -> #DIV/0! | L17: =IF(J17="","",SUMIF($F$3:$F$18,J17,$G$3:$G$18)) -> 0 | M17: =IF(J17="","",D17) -> #DIV/0! | N17: =IF(J17="","",SUMIF($F$3:$F$18,J17,$H$3:$H$18)) -> 0
A18: 104 | B18: =INDEX('Uncalibrated Data'!$A$2:$E$109, Calibration!A18, 2) -> 0 | C18: =INDEX('Uncalibrated Data'!$A$2:$E$109, Calibration!A18, 4) -> #DIV/0! | D18: =INDEX('Uncalibrated Data'!$A$2:$E$109, Calibration!A18, 5) -> #DIV/0! | F18: =IF('Tray Configuration'!C46="","",'Tray Configuration'!C46) | J18: =IF(A18="","",B18) -> 0 | K18: =IF(J18="","",C18) -> #DIV/0! | L18: =IF(J18="","",SUMIF($F$3:$F$18,J18,$G$3:$G$18)) -> 0 | M18: =IF(J18="","",D18) -> #DIV/0! | N18: =IF(J18="","",SUMIF($F$3:$F$18,J18,$H$3:$H$18)) -> 0
A19: 105 | B19: =INDEX('Uncalibrated Data'!$A$2:$E$109, Calibration!A19, 2) -> 0 | C19: =INDEX('Uncalibrated Data'!$A$2:$E$109, Calibration!A19, 4) -> #DIV/0! | D19: =INDEX('Uncalibrated Data'!$A$2:$E$109, Calibration!A19, 5) -> #DIV/0! | J19: =IF(A19="","",B19) -> 0 | K19: =IF(J19="","",C19) -> #DIV/0! | L19: =IF(J19="","",SUMIF($F$3:$F$18,J19,$G$3:$G$18)) -> 0 | M19: =IF(J19="","",D19) -> #DIV/0! | N19: =IF(J19="","",SUMIF($F$3:$F$18,J19,$H$3:$H$18)) -> 0
A22: Calibration Results
A23: CALIBRATION 1
B24: d(18_16) | C24: dD
A25: Slope | B25: =IF(A3="",1,SLOPE(L3:L7,K3:K7)) -> 1.0168445 | C25: =IF(A3="",0,SLOPE(N3:N7,M3:M7)) -> 1.0077768
A26: Intercept | B26: =IF(A3="",1,INTERCEPT(L3:L7,K3:K7)) -> 0.092702407 | C26: =IF(A3="",0,INTERCEPT(N3:N7,M3:M7)) -> 0.30914361
A27: R^2 | B27: =RSQ(L3:L7,K3:K7) -> 0.99974418 | C27: =RSQ(N3:N7,M3:M7) -> 0.99981491
A28: CALIBRATION 2
B29: d(18_16) | C29: dD
A30: Slope | B30: =IF(A8="",1,SLOPE(L8:L11,K8:K11)) -> 1.0136273 | C30: =IF(A8="",0,SLOPE(N8:N11,M8:M11)) -> 1.0075611
A31: Intercept | B31: =IF(A8="",1,INTERCEPT(L8:L11,K8:K11)) -> 0.072305893 | C31: =IF(A8="",0,INTERCEPT(N8:N11,M8:M11)) -> -0.02584803
A32: R^2 | B32: =RSQ(L8:L11,K8:K11) -> 0.99973962 | C32: =RSQ(N8:N11,M8:M11) -> 0.9999388
A33: CALIBRATION 3
B34: d(18_16) | C34: dD
A35: Slope | B35: =IF(A13="",1,SLOPE(L12:L15,K12:K15)) -> 1.0122709 | C35: =IF(A13="",0,SLOPE(N12:N15,M12:M15)) -> 1.0030752
A36: Intercept | B36: =IF(A13="",1,INTERCEPT(L12:L15,K12:K15)) -> -0.0026140035 | C36: =IF(A13="",0,INTERCEPT(N12:N15,M12:M15)) -> -0.4714866
A37: R^2 | B37: =RSQ(L12:L15,K12:K15) -> 0.99951062 | C37: =RSQ(N12:N15,M12:M15) -> 0.99989022

Sheet QAQC + Calibrated Data
A1: ='[1]Uncalibrated Data'!B1 -> Sample ID | B1: ='[1]Uncalibrated Data'!D1 -> d(18_16) | C1: ='[1]Uncalibrated Data'!E1 -> d(D_H) | F1: QC | I1: PASS? | L1: d18_16 | O1: dD | U1: LMWL (Waco, TX)
A2: ='Uncalibrated Data'!B2 -> Ouachita | B2: =IF('Uncalibrated Data'!D2="","",Calibration!$B$25*'Uncalibrated Data'!D2+Calibration!$B$26) -> -5.5099076 | C2: =IF('Uncalibrated Data'!E2="","",Calibration!$C$25*'Uncalibrated Data'!E2+Calibration!$C$26) -> -29.764327 | F2: Sample ID | G2: d(18_16) | H2: d(D_H) | I2: YES/NO | L2: 0.1 | M2: Actual | N2: -0.1 | O2: 0.1 | P2: Actual | Q2: -0.1 | U2: d(18_16) | V2: d(D_H)
A3: ='Uncalibrated Data'!B3 -> Sipsey | B3: =IF('Uncalibrated Data'!D3="","",Calibration!$B$25*'Uncalibrated Data'!D3+Calibration!$B$26) -> -4.5317031 | C3: =IF('Uncalibrated Data'!E3="","",Calibration!$C$25*'Uncalibrated Data'!E3+Calibration!$C$26) -> -22.52345 | F3: =A6 -> Ouachita | G3: =B6 -> -5.478182 | H3: =C6 -> -29.332393 | I3: =IF(AND($L$3 <=G3, G3<= $N$3, $O$3<=H3, H3<=$Q$3),"YES","NO") -> YES | K3: Sipsey | L3: =M3*1.1 -> -6.05 | M3: ='Tray Configuration'!D35 -> -5.5 | N3: =M3*0.9 -> -4.95 | O3: =P3*1.1 -> -32.56 | P3: ='Tray Configuration'!E35 -> -29.6 | Q3: =P3*0.9 -> -26.64 | U3: -10 | V3: =7.11*U3+9.52 -> -61.58
A4: ='Uncalibrated Data'!B4 -> Iceland | B4: =IF('Uncalibrated Data'!D4="","",Calibration!$B$25*'Uncalibrated Data'!D4+Calibration!$B$26) -> -8.0028036 | C4: =IF('Uncalibrated Data'!E4="","",Calibration!$C$25*'Uncalibrated Data'!E4+Calibration!$C$26) -> -52.820647 | F4: =A15 -> Ouachita | G4: =B15 -> -5.3647022 | H4: =C15 -> -29.296987 | I4: =IF(AND($L$3 <=G4, G4<= $N$3, $O$3<=H4, H4<=$Q$3),"YES","NO") -> YES | U4: 1 | V4: =7.11*U4+9.52 -> 16.63
A5: ='Uncalibrated Data'!B5 -> Sipsey | B5: =IF('Uncalibrated Data'!D5="","",Calibration!$B$25*'Uncalibrated Data'!D5+Calibration!$B$26) -> -4.4774036 | C5: =IF('Uncalibrated Data'!E5="","",Calibration!$C$25*'Uncalibrated Data'!E5+Calibration!$C$26) -> -22.359183 | F5: =A22 -> Ouachita | G5: =B22 -> -5.5067215 | H5: =C22 -> -29.370555 | I5: =IF(AND($L$3 <=G5, G5<= $N$3, $O$3<=H5, H5<=$Q$3),"YES","NO") -> YES
A6: ='Uncalibrated Data'!B6 -> Ouachita | B6: =IF('Uncalibrated Data'!D6="","",Calibration!$B$25*'Uncalibrated Data'!D6+Calibration!$B$26) -> -5.478182 | C6: =IF('Uncalibrated Data'!E6="","",Calibration!$C$25*'Uncalibrated Data'!E6+Calibration!$C$26) -> -29.332393 | F6: =A29 -> Ouachita | G6: =B29 -> -5.5084162 | H6: =C29 -> -29.297995 | I6: =IF(AND($L$3 <=G6, G6<= $N$3, $O$3<=H6, H6<=$Q$3),"YES","NO") -> YES | K6: Checking Reps: April Run | L6: d(18_16) | M6: d(D) | N6: January Run | O6: d(18_16) | P6: d(D)
A7: ='Uncalibrated Data'!B7 -> WAIS_01M01_2_RAW_20210809 | B7: =IF('Uncalibrated Data'!D7="","",Calibration!$B$25*'Uncalibrated Data'!D7+Calibration!$B$26) -> 0.19065843 | C7: =IF('Uncalibrated Data'!E7="","",Calibration!$C$25*'Uncalibrated Data'!E7+Calibration!$C$26) -> 2.6710365 | F7: =A36 -> Ouachita | G7: =B36 -> -5.4993324 | H7: =C36 -> -29.250562 | I7: =IF(AND($L$3 <=G7, G7<= $N$3, $O$3<=H7, H7<=$Q$3),"YES","NO") -> YES | K7: WAIS_01M01_2_RAW_20210809 | L7: 0.2 | M7: 2.7 | N7: WAIS_01M01_1_RAW_20210809 | O7: 0.16325817 | P7: 2.0478193
A8: ='Uncalibrated Data'!B8 -> WAIS_02M06_2_RAW_20210809 | B8: =IF('Uncalibrated Data'!D8="","",Calibration!$B$25*'Uncalibrated Data'!D8+Calibration!$B$26) -> -1.4308696 | C8: =IF('Uncalibrated Data'!E8="","",Calibration!$C$25*'Uncalibrated Data'!E8+Calibration!$C$26) -> -11.736476 | F8: =A43 -> Ouachita | G8: =B43 -> -5.450949 | H8: =C43 -> -29.376438 | I8: =IF(AND($L$3 <=G8, G8<= $N$3, $O$3<=H8, H8<=$Q$3),"YES","NO") -> YES | K8: WAIS_02M06_2_RAW_20210809 | L8: -1.4 | M8: -11.7 | N8: WAIS_02M06_1_RAW_20210809 | O8: -1.5381645 | P8: -12.639995
A9: ='Uncalibrated Data'!B9 -> WAIS_02M07_2_RAW_20210809 | B9: =IF('Uncalibrated Data'!D9="","",Calibration!$B$25*'Uncalibrated Data'!D9+Calibration!$B$26) -> -1.8597521 | C9: =IF('Uncalibrated Data'!E9="","",Calibration!$C$25*'Uncalibrated Data'!E9+Calibration!$C$26) -> -17.596362 | F9: =A50 -> Ouachita | G9: =B50 -> -5.4465567 | H9: =C50 -> -29.185673 | I9: =IF(AND($L$3 <=G9, G9<= $N$3, $O$3<=H9, H9<=$Q$3),"YES","NO") -> YES | K9: WAIS_02M07_2_RAW_20210809 | L9: -1.9 | M9: -17.6 | N9: WAIS_02M07_1_RAW_20210809 | O9: -2.4522861 | P9: -18.379132
A10: ='Uncalibrated Data'!B10 -> WAIS_SFM01_1_RAW_20211214 | B10: =IF('Uncalibrated Data'!D10="","",Calibration!$B$25*'Uncalibrated Data'!D10+Calibration!$B$26) -> -5.6616208 | C10: =IF('Uncalibrated Data'!E10="","",Calibration!$C$25*'Uncalibrated Data'!E10+Calibration!$C$26) -> -35.29561 | F10: =A57 -> Ouachita | G10: =B57 -> -5.2809975 | H10: =C57 -> -28.948897 | I10: =IF(AND($L$3 <=G10, G10<= $N$3, $O$3<=H10, H10<=$Q$3),"YES","NO") -> YES
A11: ='Uncalibrated Data'!B11 -> WAIS_N01B_1_RAW_20210903 | B11: =IF('Uncalibrated Data'!D11="","",Calibration!$B$25*'Uncalibrated Data'!D11+Calibration!$B$26) -> -5.3880896 | C11: =IF('Uncalibrated Data'!E11="","",Calibration!$C$25*'Uncalibrated Data'!E11+Calibration!$C$26) -> -29.153211 | F11: =A64 -> Ouachita | G11: =B64 -> -5.4323659 | H11: =C64 -> -29.183658 | I11: =IF(AND($L$3 <=G11, G11<= $N$3, $O$3<=H11, H11<=$Q$3),"YES","NO") -> YES
A12: ='Uncalibrated Data'!B12 -> WAIS_N4DWSeep1_RAW_20220211 | B12: =IF('Uncalibrated Data'!D12="","",Calibration!$B$25*'Uncalibrated Data'!D12+Calibration!$B$26) -> -6.1605525 | C12: =IF('Uncalibrated Data'!E12="","",Calibration!$C$25*'Uncalibrated Data'!E12+Calibration!$C$26) -> -38.873218 | F12: =A71 -> Ouachita | G12: =B71 -> -5.4158775 | H12: =C71 -> -29.248948 | I12: =IF(AND($L$3 <=G12, G12<= $N$3, $O$3<=H12, H12<=$Q$3),"YES","NO") -> YES
A13: ='Uncalibrated Data'!B13 -> WAIS_N4DWSeep2_RAW_20220211 | B13: =IF('Uncalibrated Data'!D13="","",Calibration!$B$25*'Uncalibrated Data'!D13+Calibration!$B$26) -> -6.2107168 | C13: =IF('Uncalibrated Data'!E13="","",Calibration!$C$25*'Uncalibrated Data'!E13+Calibration!$C$26) -> -39.239377 | F13: =A78 -> Ouachita | G13: =B78 -> -5.453018 | H13: =C78 -> -29.489448 | I13: =IF(AND($L$3 <=G13, G13<= $N$3, $O$3<=H13, H13<=$Q$3),"YES","NO") -> YES
A14: ='Uncalibrated Data'!B14 -> WAIS_N4DSeep4_RAW_20220211 | B14: =IF('Uncalibrated Data'!D14="","",Calibration!$B$25*'Uncalibrated Data'!D14+Calibration!$B$26) -> -6.0541228 | C14: =IF('Uncalibrated Data'!E14="","",Calibration!$C$25*'Uncalibrated Data'!E14+Calibration!$C$26) -> -38.391165 | F14: =A85 -> Ouachita | G14: =B85 -> -5.5097052 | H14: =C85 -> -29.715474 | I14: =IF(AND($L$3 <=G14, G14<= $N$3, $O$3<=H14, H14<=$Q$3),"YES","NO") -> YES
A15: ='Uncalibrated Data'!B15 -> Ouachita | B15: =IF('Uncalibrated Data'!D15="","",Calibration!$B$25*'Uncalibrated Data'!D15+Calibration!$B$26) -> -5.3647022 | C15: =IF('Uncalibrated Data'!E15="","",Calibration!$C$25*'Uncalibrated Data'!E15+Calibration!$C$26) -> -29.296987
A16: ='Uncalibrated Data'!B16 -> WAIS_N2BSeepB_RAW_20220211 | B16: =IF('Uncalibrated Data'!D16="","",Calibration!$B$25*'Uncalibrated Data'!D16+Calibration!$B$26) -> -6.078527 | C16: =IF('Uncalibrated Data'!E16="","",Calibration!$C$25*'Uncalibrated Data'!E16+Calibration!$C$26) -> -38.307183
A17: ='Uncalibrated Data'!B17 -> WAIS_33Eis_1_Filt_20220113 | B17: =IF('Uncalibrated Data'!D17="","",Calibration!$B$25*'Uncalibrated Data'!D17+Calibration!$B$26) -> -5.7307662 | C17: =IF('Uncalibrated Data'!E17="","",Calibration!$C$25*'Uncalibrated Data'!E17+Calibration!$C$26) -> -36.788799
A18: ='Uncalibrated Data'!B18 -> WAIS_ENM01_1_RAW_20211123 | B18: =IF('Uncalibrated Data'!D18="","",Calibration!$B$25*'Uncalibrated Data'!D18+Calibration!$B$26) -> -4.8867852 | C18: =IF('Uncalibrated Data'!E18="","",Calibration!$C$25*'Uncalibrated Data'!E18+Calibration!$C$26) -> -29.946331
A19: ='Uncalibrated Data'!B19 -> WAIS_ENM03_1_RAW_20210827 | B19: =IF('Uncalibrated Data'!D19="","",Calibration!$B$25*'Uncalibrated Data'!D19+Calibration!$B$26) -> -3.8604502 | C19: =IF('Uncalibrated Data'!E19="","",Calibration!$C$25*'Uncalibrated Data'!E19+Calibration!$C$26) -> -23.741785
A20: ='Uncalibrated Data'!B20 -> 4_6_MOR_DUP_N4D_20220113 | B20: =IF('Uncalibrated Data'!D20="","",Calibration!$B$25*'Uncalibrated Data'!D20+Calibration!$B$26) -> -5.8727855 | C20: =IF('Uncalibrated Data'!E20="","",Calibration!$C$25*'Uncalibrated Data'!E20+Calibration!$C$26) -> -36.742442
A21: ='Uncalibrated Data'!B21 -> 4_6_Eis2_DUP_20220113 | B21: =IF('Uncalibrated Data'!D21="","",Calibration!$B$25*'Uncalibrated Data'!D21+Calibration!$B$26) -> -5.9314235 | C21: =IF('Uncalibrated Data'!E21="","",Calibration!$C$25*'Uncalibrated Data'!E21+Calibration!$C$26) -> -37.51104
A22: ='Uncalibrated Data'!B22 -> Ouachita | B22: =IF('Uncalibrated Data'!D22="","",Calibration!$B$25*'Uncalibrated Data'!D22+Calibration!$B$26) -> -5.5067215 | C22: =IF('Uncalibrated Data'!E22="","",Calibration!$C$25*'Uncalibrated Data'!E22+Calibration!$C$26) -> -29.370555
A23: ='Uncalibrated Data'!B23 -> 3_5_MOR_N4D_DUP_20220113 | B23: =IF('Uncalibrated Data'!D23="","",Calibration!$B$25*'Uncalibrated Data'!D23+Calibration!$B$26) -> -5.8768529 | C23: =IF('Uncalibrated Data'!E23="","",Calibration!$C$25*'Uncalibrated Data'!E23+Calibration!$C$26) -> -36.828103
A24: ='Uncalibrated Data'!B24 -> WAIS_ENM03_1_RAW_20210811 | B24: =IF('Uncalibrated Data'!D24="","",Calibration!$B$25*'Uncalibrated Data'!D24+Calibration!$B$26) -> -4.0207727 | C24: =IF('Uncalibrated Data'!E24="","",Calibration!$C$25*'Uncalibrated Data'!E24+Calibration!$C$26) -> -24.882925
A25: ='Uncalibrated Data'!B25 -> WAIS_ENM01_1_RAW_20210916 | B25: =IF('Uncalibrated Data'!D25="","",Calibration!$B$25*'Uncalibrated Data'!D25+Calibration!$B$26) -> -4.6966353 | C25: =IF('Uncalibrated Data'!E25="","",Calibration!$C$25*'Uncalibrated Data'!E25+Calibration!$C$26) -> -28.717851
A26: ='Uncalibrated Data'!B26 -> WAIS_ENM03_1_RAW_20211015 | B26: =IF('Uncalibrated Data'!D26="","",Calibration!$B$25*'Uncalibrated Data'!D26+Calibration!$B$26) -> -5.6748398 | C26: =IF('Uncalibrated Data'!E26="","",Calibration!$C$25*'Uncalibrated Data'!E26+Calibration!$C$26) -> -29.349055
... A36: ='Uncalibrated Data'!B36 -> Ouachita | B36: =IF('Uncalibrated Data'!D36="","",Calibration!$B$25*'Uncalibrated Data'!D36+Calibration!$B$26) -> -5.4993324 | C36: =IF('Uncalibrated Data'!E36="","",Calibration!$C$25*'Uncalibrated Data'!E36+Calibration!$C$26) -> -29.250562
A37: ='Uncalibrated Data'!B37 -> TLM01 20220131 | B37: =IF('Uncalibrated Data'!D37="","",Calibration!$B$30*'Uncalibrated Data'!D37+Calibration!$B$31) -> -4.7599931 | C37: =IF('Uncalibrated Data'!E37="","",Calibration!$C$30*'Uncalibrated Data'!E37+Calibration!$C$31) -> -24.38095
A38: ='Uncalibrated Data'!B38 -> TLP01 20220124 | B38: =IF('Uncalibrated Data'!D38="","",Calibration!$B$30*'Uncalibrated Data'!D38+Calibration!$B$31) -> -4.757628 | C38: =IF('Uncalibrated Data'!E38="","",Calibration!$C$30*'Uncalibrated Data'!E38+Calibration!$C$31) -> -24.310085
A39: ='Uncalibrated Data'!B39 -> TLM01 20220124 | B39: =IF('Uncalibrated Data'!D39="","",Calibration!$B$30*'Uncalibrated Data'!D39+Calibration!$B$31) -> -4.711339 | C39: =IF('Uncalibrated Data'!E39="","",Calibration!$C$30*'Uncalibrated Data'!E39+Calibration!$C$31) -> -23.915793
A40: ='Uncalibrated Data'!B40 -> TLC01 20220124 | B40: =IF('Uncalibrated Data'!D40="","",Calibration!$B$30*'Uncalibrated Data'!D40+Calibration!$B$31) -> -4.7339767 | C40: =IF('Uncalibrated Data'!E40="","",Calibration!$C$30*'Uncalibrated Data'!E40+Calibration!$C$31) -> -24.127717
A41: ='Uncalibrated Data'!B41 -> TLM10 20220124 | B41: =IF('Uncalibrated Data'!D41="","",Calibration!$B$30*'Uncalibrated Data'!D41+Calibration!$B$31) -> -4.697824 | C41: =IF('Uncalibrated Data'!E41="","",Calibration!$C$30*'Uncalibrated Data'!E41+Calibration!$C$31) -> -23.752232
A42: ='Uncalibrated Data'!B42 -> TLM06 20220124 | B42: =IF('Uncalibrated Data'!D42="","",Calibration!$B$30*'Uncalibrated Data'!D42+Calibration!$B$31) -> -4.689715 | C42: =IF('Uncalibrated Data'!E42="","",Calibration!$C$30*'Uncalibrated Data'!E42+Calibration!$C$31) -> -23.822426
A43: ='Uncalibrated Data'!B43 -> Ouachita | B43: =IF('Uncalibrated Data'!D43="","",Calibration!$B$30*'Uncalibrated Data'!D43+Calibration!$B$31) -> -5.450949 | C43: =IF('Uncalibrated Data'!E43="","",Calibration!$C$30*'Uncalibrated Data'!E43+Calibration!$C$31) -> -29.376438
A44: ='Uncalibrated Data'!B44 -> TLA01 20220124 | B44: =IF('Uncalibrated Data'!D44="","",Calibration!$B$30*'Uncalibrated Data'!D44+Calibration!$B$31) -> -4.8127017 | C44: =IF('Uncalibrated Data'!E44="","",Calibration!$C$30*'Uncalibrated Data'!E44+Calibration!$C$31) -> -24.532756
A45: ='Uncalibrated Data'!B45 -> TLM16 20220124 | B45: =IF('Uncalibrated Data'!D45="","",Calibration!$B$30*'Uncalibrated Data'!D45+Calibration!$B$31) -> -4.7093118 | C45: =IF('Uncalibrated Data'!E45="","",Calibration!$C$30*'Uncalibrated Data'!E45+Calibration!$C$31) -> -23.61957
A46: ='Uncalibrated Data'!B46 -> TLM19 20220124 | B46: =IF('Uncalibrated Data'!D46="","",Calibration!$B$30*'Uncalibrated Data'!D46+Calibration!$B$31) -> -4.6441017 | C46: =IF('Uncalibrated Data'!E46="","",Calibration!$C$30*'Uncalibrated Data'!E46+Calibration!$C$31) -> -23.169862
A47: ='Uncalibrated Data'!B47 -> TLM01 20220330 | B47: =IF('Uncalibrated Data'!D47="","",Calibration!$B$30*'Uncalibrated Data'!D47+Calibration!$B$31) -> -4.6055839 | C47: =IF('Uncalibrated Data'!E47="","",Calibration!$C$30*'Uncalibrated Data'!E47+Calibration!$C$31) -> -22.922002
A48: ='Uncalibrated Data'!B48 -> TLC01 20220330 | B48: =IF('Uncalibrated Data'!D48="","",Calibration!$B$30*'Uncalibrated Data'!D48+Calibration!$B$31) -> -4.6474805 | C48: =IF('Uncalibrated Data'!E48="","",Calibration!$C$30*'Uncalibrated Data'!E48+Calibration!$C$31) -> -23.405295
... A71: ='Uncalibrated Data'!B71 -> Ouachita | B71: =IF('Uncalibrated Data'!D71="","",Calibration!$B$30*'Uncalibrated Data'!D71+Calibration!$B$31) -> -5.4158775 | C71: =IF('Uncalibrated Data'!E71="","",Calibration!$C$30*'Uncalibrated Data'!E71+Calibration!$C$31) -> -29.248948
...

Sheet Data Export
A1: Sample ID | B1: d(18_16) | C1: d(D_H)
A2: WAIS_01M01_2_RAW_20210809 | B2: 0.19065843 | C2: 2.6710365
A3: WAIS_02M06_2_RAW_20210809 | B3: -1.4308696 | C3: -11.736476
A4: WAIS_02M07_2_RAW_20210809 | B4: -1.8597521 | C4: -17.596362
A5: WAIS_SFM01_1_RAW_20211214 | B5: -5.6616208 | C5: -35.29561
A6: WAIS_N01B_1_RAW_20210903 | B6: -5.3880896 | C6: -29.153211
A7: WAIS_N4DWSeep1_RAW_20220211 | B7: -6.1605525 | C7: -38.873218
A8: WAIS_N4DWSeep2_RAW_20220211 | B8: -6.2107168 | C8: -39.239377
A9: WAIS_N4DSeep4_RAW_20220211 | B9: -6.0541228 | C9: -38.391165
A10: WAIS_N2BSeepB_RAW_20220211 | B10: -6.078527 | C10: -38.307183
A11: WAIS_33Eis_1_Filt_20220113 | B11: -5.7307662 | C11: -36.788799
A12: WAIS_ENM01_1_RAW_20211123 | B12: -4.8867852 | C12: -29.946331
A13: WAIS_ENM03_1_RAW_20210827 | B13: -3.8604502 | C13: -23.741785
... A66: WAIS_02M09_1_RAW_NODATE | B66: -5.9250737 | C66: -37.029899

Sheet Sheet1
A1: data start | B1: data end | C1: text d18 | D1: equation | E1: text dD | F1: equation | I1: text Pnumber | J1: equation
A2: 164 | B2: 166 | C2: ="average('Picarro Output'!F"&A2&":F"&B2&")" -> average('Picarro Output'!F164:F166) | D2: AVERAGE('Picarro Output'!F164:F166) | E2: ="average('Picarro Output'!G"&A2&":G"&B2&")" -> average('Picarro Output'!G164:G166) | F2: AVERAGE('Picarro Output'!G164:G166) | I2: ="'Picarro Output'!B"&B2 -> 'Picarro Output'!B166 | J2: 'Picarro Output'!B166
A3: =A2+6 -> 170 | B3: =B2+6 -> 172 | C3: ="average('Picarro Output'!F"&A3&":F"&B3&")" -> average('Picarro Output'!F170:F172) | D3: average('Picarro Output'!F170:F172) | E3: ="average('Picarro Output'!G"&A3&":G"&B3&")" -> average('Picarro Output'!G170:G172) | F3: average('Picarro Output'!G170:G172) | I3: ="'Picarro Output'!B"&B3 -> 'Picarro Output'!B172 | J3: 'Picarro Output'!B172
A4: =A3+6 -> 176 | B4: =B3+6 -> 178 | C4: ="average('Picarro Output'!F"&A4&":F"&B4&")" -> average('Picarro Output'!F176:F178) | D4: average('Picarro Output'!F176:F178) | E4: ="average('Picarro Output'!G"&A4&":G"&B4&")" -> average('Picarro Output'!G176:G178) | F4: average('Picarro Output'!G176:G178) | I4: ="'Picarro Output'!B"&B4 -> 'Picarro Output'!B178 | J4: 'Picarro Output'!B178
A5: =A4+6 -> 182 | B5: =B4+6 -> 184 | C5: ="average('Picarro Output'!F"&A5&":F"&B5&")" -> average('Picarro Output'!F182:F184) | D5: average('Picarro Output'!F182:F184) | E5: ="average('Picarro Output'!G"&A5&":G"&B5&")" -> average('Picarro Output'!G182:G184) | F5: average('Picarro Output'!G182:G184) | I5: ="'Picarro Output'!B"&B5 -> 'Picarro Output'!B184 | J5: 'Picarro Output'!B184
A6: =A5+6 -> 188 | B6: =B5+6 -> 190 | C6: ="average('Picarro Output'!F"&A6&":F"&B6&")" -> average('Picarro Output'!F188:F190) | D6: average('Picarro Output'!F188:F190) | E6: ="average('Picarro Output'!G"&A6&":G"&B6&")" -> average('Picarro Output'!G188:G190) | F6: average('Picarro Output'!G188:G190) | I6: ="'Picarro Output'!B"&B6 -> 'Picarro Output'!B190 | J6: 'Picarro Output'!B190
A7: =A6+6 -> 194 | B7: =B6+6 -> 196 | C7: ="average('Picarro Output'!F"&A7&":F"&B7&")" -> average('Picarro Output'!F194:F196) | D7: average('Picarro Output'!F194:F196) | E7: ="average('Picarro Output'!G"&A7&":G"&B7&")" -> average('Picarro Output'!G194:G196) | F7: average('Picarro Output'!G194:G196) | I7: ="'Picarro Output'!B"&B7 -> 'Picarro Output'!B196 | J7: 'Picarro Output'!B196
A8: =A7+6 -> 200 | B8: =B7+6 -> 202 | C8: ="average('Picarro Output'!F"&A8&":F"&B8&")" -> average('Picarro Output'!F200:F202) | D8: average('Picarro Output'!F200:F202) | E8: ="average('Picarro Output'!G"&A8&":G"&B8&")" -> average('Picarro Output'!G200:G202) | F8: average('Picarro Output'!G200:G202) | I8: ="'Picarro Output'!B"&B8 -> 'Picarro Output'!B202 | J8: 'Picarro Output'!B202
A9: =A8+6 -> 206 | B9: =B8+6 -> 208 | C9: ="average('Picarro Output'!F"&A9&":F"&B9&")" -> average('Picarro Output'!F206:F208) | D9: average('Picarro Output'!F206:F208) | E9: ="average('Picarro Output'!G"&A9&":G"&B9&")" -> average('Picarro Output'!G206:G208) | F9: average('Picarro Output'!G206:G208) | I9: ="'Picarro Output'!B"&B9 -> 'Picarro Output'!B208 | J9: 'Picarro Output'!B208
A10: =A9+6 -> 212 | B10: =B9+6 -> 214 | C10: ="average('Picarro Output'!F"&A10&":F"&B10&")" -> average('Picarro Output'!F212:F214) | D10: average('Picarro Output'!F212:F214) | E10: ="average('Picarro Output'!G"&A10&":G"&B10&")" -> average('Picarro Output'!G212:G214) | F10: average('Picarro Output'!G212:G214) | I10: ="'Picarro Output'!B"&B10 -> 'Picarro Output'!B214 | J10: 'Picarro Output'!B214
A11: =A10+6 -> 218 | B11: =B10+6 -> 220 | C11: ="average('Picarro Output'!F"&A11&":F"&B11&")" -> average('Picarro Output'!F218:F220) | D11: average('Picarro Output'!F218:F220) | E11: ="average('Picarro Output'!G"&A11&":G"&B11&")" -> average('Picarro Output'!G218:G220) | F11: average('Picarro Output'!G218:G220) | I11: ="'Picarro Output'!B"&B11 -> 'Picarro Output'!B220 | J11: 'Picarro Output'!B220
A12: =A11+6 -> 224 | B12: =B11+6 -> 226 | C12: ="average('Picarro Output'!F"&A12&":F"&B12&")" -> average('Picarro Output'!F224:F226) | D12: average('Picarro Output'!F224:F226) | E12: ="average('Picarro Output'!G"&A12&":G"&B12&")" -> average('Picarro Output'!G224:G226) | F12: average('Picarro Output'!G224:G226) | I12: ="'Picarro Output'!B"&B12 -> 'Picarro Output'!B226 | J12: 'Picarro Output'!B226
A13: =A12+6 -> 230 | B13: =B12+6 -> 232 | C13: ="average('Picarro Output'!F"&A13&":F"&B13&")" -> average('Picarro Output'!F230:F232) | D13: average('Picarro Output'!F230:F232) | E13: ="average('Picarro Output'!G"&A13&":G"&B13&")" -> average('Picarro Output'!G230:G232) | F13: average('Picarro Output'!G230:G232) | I13: ="'Picarro Output'!B"&B13 -> 'Picarro Output'!B232 | J13: 'Picarro Output'!B232
A15: 243 | B15: 247 | C15: ="average('Picarro Output'!F"&A15&":F"&B15&")" -> average('Picarro Output'!F243:F247) | D15: average('Picarro Output'!F243:F247) | E15: ="average('Picarro Output'!G"&A15&":G"&B15&")" -> average('Picarro Output'!G243:G247) | F15: average('Picarro Output'!G243:G247) | I15: ="'Picarro Output'!B"&B15 -> 'Picarro Output'!B247 | J15: 'Picarro Output'!B247
A16: =A15+15 -> 258 | B16: =B15+15 -> 262 | C16: ="average('Picarro Output'!F"&A16&":F"&B16&")" -> average('Picarro Output'!F258:F262) | D16: average('Picarro Output'!F258:F262) | E16: ="average('Picarro Output'!G"&A16&":G"&B16&")" -> average('Picarro Output'!G258:G262) | F16: average('Picarro Output'!G258:G262) | I16: ="'Picarro Output'!B"&B16 -> 'Picarro Output'!B262 | J16: 'Picarro Output'!B262
A17: =A16+15 -> 273 | B17: =B16+15 -> 277 | C17: ="average('Picarro Output'!F"&A17&":F"&B17&")" -> average('Picarro Output'!F273:F277) | D17: average('Picarro Output'!F273:F277) | E17: ="average('Picarro Output'!G"&A17&":G"&B17&")" -> average('Picarro Output'!G273:G277) | F17: average('Picarro Output'!G273:G277) | I17: ="'Picarro Output'!B"&B17 -> 'Picarro Output'!B277 | J17: 'Picarro Output'!B277
A18: =A17+15 -> 288 | B18: =B17+15 -> 292 | C18: ="average('Picarro Output'!F"&A18&":F"&B18&")" -> average('Picarro Output'!F288:F292) | D18: average('Picarro Output'!F288:F292) | E18: ="average('Picarro Output'!G"&A18&":G"&B18&")" -> average('Picarro Output'!G288:G292) | F18: average('Picarro Output'!G288:G292) | I18: ="'Picarro Output'!B"&B18 -> 'Picarro Output'!B292 | J18: 'Picarro Output'!B292
A20: 296 | B20: 298 | C20: ="average('Picarro Output'!F"&A20&":F"&B20&")" -> average('Picarro Output'!F296:F298) | D20: average('Picarro Output'!F296:F298) | E20: ="average('Picarro Output'!G"&A20&":G"&B20&")" -> average('Picarro Output'!G296:G298) | F20: average('Picarro Output'!G296:G298) | I20: ="'Picarro Output'!B"&B20 -> 'Picarro Output'!B298 | J20: 'Picarro Output'!B298
A21: =A20+6 -> 302 | B21: =B20+6 -> 304 | C21: ="average('Picarro Output'!F"&A21&":F"&B21&")" -> average('Picarro Output'!F302:F304) | D21: average('Picarro Output'!F302:F304) | E21: ="average('Picarro Output'!G"&A21&":G"&B21&")" -> average('Picarro Output'!G302:G304) | F21: average('Picarro Output'!G302:G304) | I21: ="'Picarro Output'!B"&B21 -> 'Picarro Output'!B304 | J21: 'Picarro Output'!B304
A22: =A21+6 -> 308 | B22: =B21+6 -> 310 | C22: ="average('Picarro Output'!F"&A22&":F"&B22&")" -> average('Picarro Output'!F308:F310) | D22: average('Picarro Output'!F308:F310) | E22: ="average('Picarro Output'!G"&A22&":G"&B22&")" -> average('Picarro Output'!G308:G310) | F22: average('Picarro Output'!G308:G310) | I22: ="'Picarro Output'!B"&B22 -> 'Picarro Output'!B310 | J22: 'Picarro Output'!B310
A23: =A22+6 -> 314 | B23: =B22+6 -> 316 | C23: ="average('Picarro Output'!F"&A23&":F"&B23&")" -> average('Picarro Output'!F314:F316) | D23: average('Picarro Output'!F314:F316) | E23: ="average('Picarro Output'!G"&A23&":G"&B23&")" -> average('Picarro Output'!G314:G316) | F23: average('Picarro Output'!G314:G316) | I23: ="'Picarro Output'!B"&B23 -> 'Picarro Output'!B316 | J23: 'Picarro Output'!B316
A24: =A23+6 -> 320 | B24: =B23+6 -> 322 | C24: ="average('Picarro Output'!F"&A24&":F"&B24&")" -> average('Picarro Output'!F320:F322) | D24: average('Picarro Output'!F320:F322) | E24: ="average('Picarro Output'!G"&A24&":G"&B24&")" -> average('Picarro Output'!G320:G322) | F24: average('Picarro Output'!G320:G322) | I24: ="'Picarro Output'!B"&B24 -> 'Picarro Output'!B322 | J24: 'Picarro Output'!B322
A25: =A24+6 -> 326 | B25: =B24+6 -> 328 | C25: ="average('Picarro Output'!F"&A25&":F"&B25&")" -> average('Picarro Output'!F326:F328) | D25: average('Picarro Output'!F326:F328) | E25: ="average('Picarro Output'!G"&A25&":G"&B25&")" -> average('Picarro Output'!G326:G328) | F25: average('Picarro Output'!G326:G328) | I25: ="'Picarro Output'!B"&B25 -> 'Picarro Output'!B328 | J25: 'Picarro Output'!B328
A26: =A25+6 -> 332 | B26: =B25+6 -> 334 | C26: ="average('Picarro Output'!F"&A26&":F"&B26&")" -> average('Picarro Output'!F332:F334) | D26: average('Picarro Output'!F332:F334) | E26: ="average('Picarro Output'!G"&A26&":G"&B26&")" -> average('Picarro Output'!G332:G334) | F26: average('Picarro Output'!G332:G334) | I26: ="'Picarro Output'!B"&B26 -> 'Picarro Output'!B334 | J26: 'Picarro Output'!B334
A27: =A26+6 -> 338 | B27: =B26+6 -> 340 | C27: ="average('Picarro Output'!F"&A27&":F"&B27&")" -> average('Picarro Output'!F338:F340) | D27: average('Picarro Output'!F338:F340) | E27: ="average('Picarro Output'!G"&A27&":G"&B27&")" -> average('Picarro Output'!G338:G340) | F27: average('Picarro Output'!G338:G340) | I27: ="'Picarro Output'!B"&B27 -> 'Picarro Output'!B340 | J27: 'Picarro Output'!B340
A28: =A27+6 -> 344 | B28: =B27+6 -> 346 | C28: ="average('Picarro Output'!F"&A28&":F"&B28&")" -> average('Picarro Output'!F344:F346) | D28: average('Picarro Output'!F344:F346) | E28: ="average('Picarro Output'!G"&A28&":G"&B28&")" -> average('Picarro Output'!G344:G346) | F28: average('Picarro Output'!G344:G346) | I28: ="'Picarro Output'!B"&B28 -> 'Picarro Output'!B346 | J28: 'Picarro Output'!B346
A29: =A28+6 -> 350 | B29: =B28+6 -> 352 | C29: ="average('Picarro Output'!F"&A29&":F"&B29&")" -> average('Picarro Output'!F350:F352) | D29: average('Picarro Output'!F350:F352) | E29: ="average('Picarro Output'!G"&A29&":G"&B29&")" -> average('Picarro Output'!G350:G352) | F29: average('Picarro Output'!G350:G352) | I29: ="'Picarro Output'!B"&B29 -> 'Picarro Output'!B352 | J29: 'Picarro Output'!B352
A30: =A29+6 -> 356 | B30: =B29+6 -> 358 | C30: ="average('Picarro Output'!F"&A30&":F"&B30&")" -> average('Picarro Output'!F356:F358) | D30: average('Picarro Output'!F356:F358) | E30: ="average('Picarro Output'!G"&A30&":G"&B30&")" -> average('Picarro Output'!G356:G358) | F30: average('Picarro Output'!G356:G358) | I30: ="'Picarro Output'!B"&B30 -> 'Picarro Output'!B358 | J30: 'Picarro Output'!B358
A31: =A30+6 -> 362 | B31: =B30+6 -> 364 | C31: ="average('Picarro Output'!F"&A31&":F"&B31&")" -> average('Picarro Output'!F362:F364) | D31: average('Picarro Output'!F362:F364) | E31: ="average('Picarro Output'!G"&A31&":G"&B31&")" -> average('Picarro Output'!G362:G364) | F31: average('Picarro Output'!G362:G364) | I31: ="'Picarro Output'!B"&B31 -> 'Picarro Output'!B364 | J31: 'Picarro Output'!B364
A32: =A31+6 -> 368 | B32: =B31+6 -> 370 | C32: ="average('Picarro Output'!F"&A32&":F"&B32&")" -> average('Picarro Output'!F368:F370) | D32: average('Picarro Output'!F368:F370) | E32: ="average('Picarro Output'!G"&A32&":G"&B32&")" -> average('Picarro Output'!G368:G370) | F32: average('Picarro Output'!G368:G370) | I32: ="'Picarro Output'!B"&B32 -> 'Picarro Output'!B370 | J32: 'Picarro Output'!B370
